Workbook

Sheet สรุป
A1: สรุปราคาค่าก่อสร้างงานหลัก (ไม่รวมงาน Preconstruction) – ฉบับแก้ไข v2
A2: งานก่อสร้างอาคารโกดังและงานบริเวณ บริษัท ตงเฉิน อีเล็คทริค เคเบิ้ล แอนด์ไวร์ จำกัด
A3: สถานที่: เลขที่ 10/7 หมู่ที่ 5 ตำบลท่าข้าม อำเภอสามพราน จังหวัดนครปฐม 73110 | อ้างอิงแบบ S201, S201-B, S202, A101, A202 (Issue 01/09/69)
A4: หมวด | B4: รายการ | C4: ค่าวัสดุ | D4: ค่าแรง | E4: รวมเป็นเงิน | F4: หมายเหตุ
A5: 1 | B5: งานเตรียมการ | C5: ='1-งานเตรียมการ'!F37 | D5: ='1-งานเตรียมการ'!H37 | E5: ='1-งานเตรียมการ'!I37 | F5: วางผัง, สิ่งอำนวยความสะดวกชั่วคราว, ถมดิน/ขุดดิน, เครื่องจักรและการทดสอบ, ความปลอดภัยและการบริหาร
A6: 2 | B6: งานโครงสร้าง | C6: ='2-งานโครงสร้าง'!F39 | D6: ='2-งานโครงสร้าง'!H39 | E6: ='2-งานโครงสร้าง'!I39 | F6: เสาเข็ม, ฐานราก, เสา-คาน คสล., พื้น คสล., โครงสร้างเหล็ก, ชั้นลอย
A7: 3 | B7: งานสถาปัตยกรรม | C7: ='3-งานสถาปัตยกรรม'!F27 | D7: ='3-งานสถาปัตยกรรม'!H27 | E7: ='3-งานสถาปัตยกรรม'!I27 | F7: หลังคาและผนังภายนอก, ผนังก่ออิฐฉาบปูน, ผิวพื้น, ประตูหน้าต่าง, ทาสี, อาคารประกอบ
A8: 4 | B8: งานบริเวณ (เพิ่มใหม่ทั้งหมวด) | C8: ='4-งานบริเวณ'!F24 | D8: ='4-งานบริเวณ'!H24 | E8: ='4-งานบริเวณ'!I24 | F8: พื้นถนน+เข็ม I22, ทางลาด, ฐานหม้อแปลง, ถังเก็บน้ำใต้ดิน, ระบายน้ำ (หมวดใหม่)
B9: รวมค่างานต้นทุน | E9: =SUM(E5:E8)
B10: ค่าบริหารโครงการและกำไร (Overhead & Profit) % | D10: 0.1
B11: ค่าบริหารโครงการและกำไร (Overhead & Profit) | E11: =E9*D10
B12: รวมราคาก่อนภาษีมูลค่าเพิ่ม | E12: =E9+E11
B13: ภาษีมูลค่าเพิ่ม 7% | E13: =E12*0.07
B14: รวมราคาเสนอทั้งสิ้น | E14: =E12+E13

Sheet 1-งานเตรียมการ
A1: บัญชีปริมาณงานและราคา หมวดที่ 1 งานเตรียมการ
A2: งานก่อสร้างอาคารโกดังและงานบริเวณ บริษัท ตงเฉิน อีเล็คทริค เคเบิ้ล แอนด์ไวร์ จำกัด
A3: สถานที่: เลขที่ 10/7 หมู่ที่ 5 ตำบลท่าข้าม อำเภอสามพราน จังหวัดนครปฐม 73110 | อ้างอิงแบบ S201, S201-B, S202, A101, A202 (Issue 01/09/69) | ฉบับแก้ไข v2 (ทวนสอบแบบ + BIM) 27/10/2569
A4: ลำดับ | B4: รายการ | C4: ปริมาณ | D4: หน่วย | E4: ค่าวัสดุ/หน่วย | F4: ค่าวัสดุรวม | G4: ค่าแรง/หน่วย | H4: ค่าแรงรวม | I4: รวมเป็นเงิน | J4: สถานะ | K4: หมายเหตุ / ที่มาของปริมาณ
A5: 1.1 | B5: หมวดงานวางผัง
A6: 1.1.1 | B6: วางผังอาคาร กำหนดแนวกริด 1-11 และ A-J ตั้งหมุดอ้างอิงถาวร (BM) และระดับ ±0.00 | C6: 1 | D6: งาน | F6: =IF(C6="",0,C6*E6) | H6: =IF(C6="",0,C6*G6) | I6: =F6+H6 | K6: ผังอาคาร 60.00 x 54.00 ม. (S201)
A7: 1.1.2 | B7: วางตำแหน่งเสาเข็มด้วยกล้องสำรวจ (Total Station) และตรวจสอบตำแหน่งหลังตอก | C7: 751 | D7: ต้น | F7: =IF(C7="",0,C7*E7) | H7: =IF(C7="",0,C7*G7) | I7: =F7+H7 | J7: แก้ไข | K7: เดิม 470 → นับจากผัง S201 ทุกชนิด (ดูหมวด 2.1 และ 4.1)
A8: 1.2 | B8: หมวดงานสิ่งอำนวยความสะดวกชั่วคราว
A9: 1.2.1 | B9: รั้วชั่วคราวแผ่นเหล็กรีดลอน (Metal Sheet) สูง 2.00 ม. โครงเหล็กกล่อง พร้อมทาสี | C9: 312 | D9: ม. | F9: =IF(C9="",0,C9*E9) | H9: =IF(C9="",0,C9*G9) | I9: =F9+H9 | J9: แก้ไข | K9: เดิม 308 (สมมติ 80x74) → เส้นรอบแนวเขตที่ดินจากผัง S202
A10: 1.2.2 | B10: ประตูรั้วชั่วคราว บานเลื่อน/บานเปิดคู่ กว้าง 6.00 ม. | C10: 1 | D10: ชุด | F10: =IF(C10="",0,C10*E10) | H10: =IF(C10="",0,C10*G10) | I10: =F10+H10
A11: 1.2.3 | B11: สำนักงานสนาม (Site Office) ขนาดไม่น้อยกว่า 3.00 x 8.00 ม. พร้อมเครื่องปรับอากาศ โต๊ะประชุม และอุปกรณ์สำนักงาน | C11: 1 | D11: หลัง | F11: =IF(C11="",0,C11*E11) | H11: =IF(C11="",0,C11*G11) | I11: =F11+H11 | K11: รวมพื้นที่สำหรับผู้ควบคุมงานของผู้ว่าจ้าง
A12: 1.2.4 | B12: โรงเก็บวัสดุและเครื่องมือ (Store) พร้อมลานกองเหล็กเสริมและลานดัดเหล็ก | C12: 1 | D12: แห่ง | F12: =IF(C12="",0,C12*E12) | H12: =IF(C12="",0,C12*G12) | I12: =F12+H12 | J12: แก้ไข | K12: พื้นที่ว่างรอบอาคารแคบ (4-14 ม.) ต้องย้ายออกก่อนงานพื้นถนน หรือเช่าพื้นที่ข้างเคียง
A13: 1.2.5 | B13: ห้องน้ำ-ห้องส้วมชั่วคราว พร้อมถังบำบัดสำเร็จรูป | C13: 2 | D13: ห้อง | F13: =IF(C13="",0,C13*E13) | H13: =IF(C13="",0,C13*G13) | I13: =F13+H13 | K13: ไม่น้อยกว่า 1 ห้อง/คนงาน 15 คน
A14: 1.2.6 | B14: ที่พักคนงาน (หากจัดภายในพื้นที่ ต้องได้รับอนุญาตจากผู้ว่าจ้าง) | C14: 1 | D14: เหมา | F14: =IF(C14="",0,C14*E14) | H14: =IF(C14="",0,C14*G14) | I14: =F14+H14
A15: 1.2.7 | B15: ระบบไฟฟ้าชั่วคราว ตู้ควบคุม เดินสายไฟ พร้อมเครื่องตัดไฟรั่ว (RCBO) | C15: 1 | D15: เหมา | F15: =IF(C15="",0,C15*E15) | H15: =IF(C15="",0,C15*G15) | I15: =F15+H15
A16: 1.2.8 | B16: ระบบประปาชั่วคราว ท่อเมน ถังพักน้ำ และปั๊มน้ำ | C16: 1 | D16: เหมา | F16: =IF(C16="",0,C16*E16) | H16: =IF(C16="",0,C16*G16) | I16: =F16+H16
A17: 1.2.9 | B17: ค่าน้ำประปาและค่าไฟฟ้าระหว่างก่อสร้าง | C17: 6 | D17: เดือน | F17: =IF(C17="",0,C17*E17) | H17: =IF(C17="",0,C17*G17) | I17: =F17+H17 | K17: แผน CPM งานหลัก 5.4 เดือน (14 ธ.ค. 69 – 27 พ.ค. 70)
A18: 1.2.10 | B18: ป้ายโครงการ ขนาด 1.20 x 2.40 ม. โครงเหล็ก พิมพ์อิงค์เจ็ท ตามที่ผู้ว่าจ้างอนุมัติ | C18: 1 | D18: ป้าย | F18: =IF(C18="",0,C18*E18) | H18: =IF(C18="",0,C18*G18) | I18: =F18+H18
A19: 1.3 | B19: หมวดงานถมดินและปรับพื้นที่
A20: 1.3.1 | B20: ถมดินปรับระดับ บดอัดเป็นชั้นหนาไม่เกิน 0.20 ม. ความแน่นไม่น้อยกว่า 95% Standard Proctor | C20: 8566 | D20: ลบ.ม. | F20: =IF(C20="",0,C20*E20) | H20: =IF(C20="",0,C20*G20) | I20: =F20+H20 | J20: แก้ไข | K20: เดิม 1,856 (ถมเฉลี่ย 0.50 ม.) → A202: ถนนอ้างอิง -1.50 / ถนนรอบอาคาร ±0.00 / FFL +0.50 ถ้าดินเดิม -1.50 = 8,566; -1.00 = 5,593; -0.50 = 2,620 ลบ.ม. ยืนยันด้วยผลสำรวจระดับ P1.2 และเสนอราคาต่อ ลบ.ม.
A21: 1.3.2 | B21: ลานทำงานเครื่องตอกเข็ม (Working Platform) ปูหินคลุก/เศษหิน | C21: 1 | D21: เหมา | F21: =IF(C21="",0,C21*E21) | H21: =IF(C21="",0,C21*G21) | I21: =F21+H21
A22: 1.3.3 | B22: รางระบายน้ำชั่วคราวและบ่อพักตะกอน ป้องกันน้ำท่วมขังและดินไหลลงพื้นที่ข้างเคียง | C22: 1 | D22: เหมา | F22: =IF(C22="",0,C22*E22) | H22: =IF(C22="",0,C22*G22) | I22: =F22+H22
A23: 1.3.4 | B23: ขุดดินฐานรากและขนย้ายดินส่วนเกิน (จากตาราง S1.1) | C23: 434.29 | D23: ลบ.ม. | F23: =IF(C23="",0,C23*E23) | H23: =IF(C23="",0,C23*G23) | I23: =F23+H23 | J23: เพิ่มใหม่ | K23: S201-B ตาราง S1.1 รวม F1/F1A/F1P/F2P (ไม่รวมถังใต้ดิน 4.4)
A24: 1.3.5 | B24: ป้องกันดินพังและสูบน้ำ งานขุดถังเก็บน้ำใต้ดิน ลึก ~3.0 ม. (Sheet pile/ค้ำยัน) | C24: 1 | D24: เหมา | F24: =IF(C24="",0,C24*E24) | H24: =IF(C24="",0,C24*G24) | I24: =F24+H24 | J24: เพิ่มใหม่ | K24: ระดับก้นถัง BF -2.85 (S202)
A25: 1.4 | B25: หมวดเครื่องจักรและการทดสอบ
A26: 1.4.1 | B26: ค่าขนย้ายเครื่องจักรเข้า-ออกพื้นที่ ปั้นจั่นตอกเข็ม และเครื่องจักรงานดิน | C26: 1 | D26: เหมา | F26: =IF(C26="",0,C26*E26) | H26: =IF(C26="",0,C26*G26) | I26: =F26+H26 | K26: แนะนำตอกเข็มทุกชนิด (รวมเข็มถนน) ในการเข้าพื้นที่ครั้งเดียว
A27: 1.4.2 | B27: ทดสอบกำลังรับน้ำหนักเสาเข็มแบบพลศาสตร์ (Dynamic Load Test) | C27: 3 | D27: ต้น | F27: =IF(C27="",0,C27*E27) | H27: =IF(C27="",0,C27*G27) | I27: =F27+H27 | J27: แก้ไข | K27: เดิม 2 → อย่างน้อย 1 ต้นต่อขนาดเข็ม (I22/I26/I35) หรือตามวิศวกรกำหนด
A28: 1.4.3 | B28: ทดสอบความแน่นดินถมในสนาม (Field Density Test) | C28: 96 | D28: จุด | F28: =IF(C28="",0,C28*E28) | H28: =IF(C28="",0,C28*G28) | I28: =F28+H28 | J28: แก้ไข | K28: เดิม 6 → พื้นที่ 5,946 ตร.ม. ÷ 500 = 12 จุด/ชั้น x 8 ชั้น (ถม 1.60 ม. ชั้นละ 0.20)
A29: 1.4.4 | B29: ทดสอบวัสดุก่อสร้าง (ตัวอย่างคอนกรีต กำลังดึงเหล็กเสริม) ตลอดโครงการ | C29: 1 | D29: เหมา | F29: =IF(C29="",0,C29*E29) | H29: =IF(C29="",0,C29*G29) | I29: =F29+H29 | K29: คอนกรีตรวม ~1,180 ลบ.ม.
A30: 1.5 | B30: หมวดความปลอดภัย การบริหาร และเอกสาร
A31: 1.5.1 | B31: ระบบความปลอดภัย: ป้ายเตือน กรวย ไฟส่องสว่าง PPE ถังดับเพลิง ชุดปฐมพยาบาล และเจ้าหน้าที่ความปลอดภัย (จป.) | C31: 6 | D31: เดือน | F31: =IF(C31="",0,C31*E31) | H31: =IF(C31="",0,C31*G31) | I31: =F31+H31
A32: 1.5.2 | B32: วิศวกรควบคุมงาน โฟร์แมน และเจ้าหน้าที่สำนักงานสนาม | C32: 6 | D32: เดือน | F32: =IF(C32="",0,C32*E32) | H32: =IF(C32="",0,C32*G32) | I32: =F32+H32
A33: 1.5.3 | B33: ประกันภัยความเสี่ยงงานก่อสร้าง (CAR) และบุคคลภายนอก (Third Party) | C33: 1 | D33: เหมา | F33: =IF(C33="",0,C33*E33) | H33: =IF(C33="",0,C33*G33) | I33: =F33+H33
A34: 1.5.4 | B34: แบบขยายการก่อสร้าง (Shop Drawing) แผนงาน รายงานประจำวัน/สัปดาห์ และภาพถ่ายความก้าวหน้า | C34: 1 | D34: เหมา | F34: =IF(C34="",0,C34*E34) | H34: =IF(C34="",0,C34*G34) | I34: =F34+H34 | K34: รวม Shop drawing โครงเหล็กหลังคา
A35: 1.5.5 | B35: แบบก่อสร้างจริง (As-Built Drawing) และเอกสารส่งมอบงาน | C35: 1 | D35: เหมา | F35: =IF(C35="",0,C35*E35) | H35: =IF(C35="",0,C35*G35) | I35: =F35+H35
A36: 1.5.6 | B36: ทำความสะอาดพื้นที่ รื้อถอนสิ่งปลูกสร้างชั่วคราว และคืนสภาพพื้นที่ก่อนส่งมอบ | C36: 1 | D36: เหมา | F36: =IF(C36="",0,C36*E36) | H36: =IF(C36="",0,C36*G36) | I36: =F36+H36
B37: รวมหมวดที่ 1 งานเตรียมการ | F37: =SUM(F5:F36) | H37: =SUM(H5:H36) | I37: =SUM(I5:I36)
B38: หมายเหตุ: ช่องสีเหลืองสำหรับกรอกราคาต่อหน่วย | สีแดง = เพิ่มใหม่ | สีส้ม = แก้ไขปริมาณ/รายละเอียด | สีม่วง = รอข้อมูล/ยืนยันจากผู้ออกแบบ

Sheet 2-งานโครงสร้าง
A1: บัญชีปริมาณงานและราคา หมวดที่ 2 งานโครงสร้าง
A2: งานก่อสร้างอาคารโกดังและงานบริเวณ บริษัท ตงเฉิน อีเล็คทริค เคเบิ้ล แอนด์ไวร์ จำกัด
A3: สถานที่: เลขที่ 10/7 หมู่ที่ 5 ตำบลท่าข้าม อำเภอสามพราน จังหวัดนครปฐม 73110 | อ้างอิงแบบ S201, S201-B, S202, A101, A202 (Issue 01/09/69) | ฉบับแก้ไข v2 (ทวนสอบแบบ + BIM) 27/10/2569
A4: ลำดับ | B4: รายการ | C4: ปริมาณ | D4: หน่วย | E4: ค่าวัสดุ/หน่วย | F4: ค่าวัสดุรวม | G4: ค่าแรง/หน่วย | H4: ค่าแรงรวม | I4: รวมเป็นเงิน | J4: สถานะ | K4: หมายเหตุ / ที่มาของปริมาณ
A5: 2.1 | B5: หมวดงานเสาเข็ม (ตอกรูปตัวไอ ยาว 22 ม. ตาม Type Mark ปรับความยาวตามผลสำรวจดิน P3)
A6: 2.1.1 | B6: เสาเข็มตอก I-260x260 ยาว 22 ม. เสริมหนวดกุ้ง 4-DB12-2.5 ม. รับฐานราก F2P (I26-22) รวมค่าตอก | C6: 92 | D6: ต้น | F6: =IF(C6="",0,C6*E6) | H6: =IF(C6="",0,C6*G6) | I6: =F6+H6 | K6: เดิม 92 ตรงกัน: 46 ฐาน x 2 ต้น (นับจาก S201)
A7: 2.1.2 | B7: เสาเข็มตอก I-350x350 ยาว 22 ม. รับพื้นโรงงาน (I35-22) ระยะ 3.00x3.00 ม. รวมค่าตอก | C7: 360 | D7: ต้น | F7: =IF(C7="",0,C7*E7) | H7: =IF(C7="",0,C7*G7) | I7: =F7+H7 | J7: แก้ไข | K7: ตรงกัน 360 ต้น; ระบุขนาด 350 มม. (ราคาต่างจากเข็มฐานราก)
A8: 2.1.3 | B8: เสาเข็มตอก I-260x260 ยาว 22 ม. อาคารประกอบ ฐาน F1P-1 (ห้องน้ำ 6, ห้องสารเคมี 3, ทางลาดเหนือ 2) รวมค่าตอก | C8: 11 | D8: ต้น | F8: =IF(C8="",0,C8*E8) | H8: =IF(C8="",0,C8*G8) | I8: =F8+H8 | J8: แก้ไข | K8: เดิม 18 → 11 (นับจาก S201)
A9: 2.1.4 | B9: เสาเข็มตอก I-260x260 รับถังเก็บน้ำใต้ดิน (ตัดหัวลดระดับ 1 ม.) รวมค่าตอก | C9: 17 | D9: ต้น | F9: =IF(C9="",0,C9*E9) | H9: =IF(C9="",0,C9*G9) | I9: =F9+H9 | J9: เพิ่มใหม่ | K9: เพิ่ม: S201-B (I26) นับจากผังได้ 17
A10: 2.1.5 | B10: ตัดหัวเสาเข็มและขนทิ้ง | C10: 751 | D10: ต้น | F10: =IF(C10="",0,C10*E10) | H10: =IF(C10="",0,C10*G10) | I10: =F10+H10 | J10: แก้ไข | K10: เดิม 470 → รวมทุกชนิดในหมวด 2.1 + 4.1 + 4.3 + 4.6
A11: 2.1.6 | B11: ราคาปรับเพิ่ม/ลดความยาวเสาเข็ม กรณีผลสำรวจดินต่างจากความยาวที่สมมติ แยกตามขนาด I22 / I26 / I35 | D11: ม. | F11: =IF(C11="",0,C11*E11) | H11: =IF(C11="",0,C11*G11) | I11: =F11+H11 | J11: แก้ไข | K11: ราคาต่อเมตร ใช้ปรับหลังได้ผลสำรวจดิน P3
A12: 2.2 | B12: หมวดงานฐานราก (ข้อมูลจากตาราง S1.1 แบบ S201-B)
A13: 2.2.1 | B13: ฐานราก F2P 0.60x1.50x0.80 ม. (เข็ม 2 ต้น) ทรายรองพื้น คอนกรีตหยาบ คอนกรีตโครงสร้าง ไม้แบบ | C13: 46 | D13: ฐาน | F13: =IF(C13="",0,C13*E13) | H13: =IF(C13="",0,C13*G13) | I13: =F13+H13 | J13: แก้ไข | K13: คอนกรีต 33.12 ลบ.ม., ทราย 11.84, คอนกรีตหยาบ 2.63, ไม้แบบ 154.6 ตร.ม.; ตารางนับ 47 แต่ปริมาตร = 46 ฐาน (ยืนยัน)
A14: 2.2.2 | B14: Drop panel F1P 1.00x1.00x0.20 ม. รับพื้นบนเข็ม I35 ทรายรองพื้น คอนกรีตหยาบ คอนกรีต | C14: 360 | D14: จุด | F14: =IF(C14="",0,C14*E14) | H14: =IF(C14="",0,C14*G14) | I14: =F14+H14 | J14: เพิ่มใหม่ | K14: เพิ่ม: คอนกรีต 72.00, ทราย 92.16, คอนกรีตหยาบ 21.78 ลบ.ม.
A15: 2.2.3 | B15: ฐาน F1P-1 0.60x0.60x0.60 ม. (เข็มเดี่ยว อาคารประกอบ) | C15: 11 | D15: ฐาน | F15: =IF(C15="",0,C15*E15) | H15: =IF(C15="",0,C15*G15) | I15: =F15+H15 | J15: เพิ่มใหม่ | K15: เพิ่ม: คอนกรีต 2.38, ทราย 1.58, คอนกรีตหยาบ 0.27 ลบ.ม.
A16: 2.2.4 | B16: เหล็กเสริมฐานราก F2P / F1P / F1P-1 | D16: กก. | F16: =IF(C16="",0,C16*E16) | H16: =IF(C16="",0,C16*G16) | I16: =F16+H16 | J16: รอข้อมูล | K16: รอเอกสารออกแบบเหล็กเสริม (อ้างอิงประมาณ 100 กก./ลบ.ม. ≈ 10,750 กก.)
A17: 2.3 | B17: หมวดงานเสาและคาน คสล.
A18: 2.3.1 | B18: เสา คสล. C1 0.30x0.50 ม. จากหลังฐานรากถึงหัวเสา +4.50 (ยาว 4.90 ม.) | C18: 45 | D18: ต้น | F18: =IF(C18="",0,C18*E18) | H18: =IF(C18="",0,C18*G18) | I18: =F18+H18 | J18: แก้ไข | K18: เดิม 'เสาตอม่อ 46' → C1 45 ต้น คอนกรีต 32.37 ลบ.ม. ไม้แบบ 352.80 ตร.ม. (S4.1)
A19: 2.3.2 | B19: เสา คสล. C2 0.50x0.50 ม. (กริด 6/J) | C19: 1 | D19: ต้น | F19: =IF(C19="",0,C19*E19) | H19: =IF(C19="",0,C19*G19) | I19: =F19+H19 | J19: เพิ่มใหม่ | K19: เพิ่ม: คอนกรีต 1.13 ลบ.ม. ไม้แบบ 9.80 ตร.ม.
A20: 2.3.3 | B20: เสา คสล. C3 0.20x0.20 ม. อาคารประกอบ | C20: 13 | D20: ต้น | F20: =IF(C20="",0,C20*E20) | H20: =IF(C20="",0,C20*G20) | I20: =F20+H20 | J20: เพิ่มใหม่ | K20: เพิ่ม: คอนกรีต 1.60 ลบ.ม. ไม้แบบ 34.74 ตร.ม. (S4.1 รวม 3 ระดับ)
A21: 2.3.4 | B21: คานคอดิน B1 0.20x0.60 ม. TOP +0.50 (แนวรอบอาคาร + แนวกริด 6) | C21: 282 | D21: ม. | F21: =IF(C21="",0,C21*E21) | H21: =IF(C21="",0,C21*G21) | I21: =F21+H21 | J21: แก้ไข | K21: เดิมว่าง → คอนกรีต 32.04 ลบ.ม. ไม้แบบ 394.80 ตร.ม. (S3)
A22: 2.3.5 | B22: คาน B3 0.20x0.40 ม. อาคารประกอบ (ระดับถนน + ระดับพื้นชั้น 1) | C22: 40.45 | D22: ม. | F22: =IF(C22="",0,C22*E22) | H22: =IF(C22="",0,C22*G22) | I22: =F22+H22 | J22: เพิ่มใหม่ | K22: เพิ่ม: คอนกรีต 1.81 ลบ.ม. ไม้แบบ 40.45 ตร.ม. (S3)
A23: 2.3.6 | B23: เหล็กเสริมเสาและคาน คสล. (C1, C2, C3, B1, B3) | D23: กก. | F23: =IF(C23="",0,C23*E23) | H23: =IF(C23="",0,C23*G23) | I23: =F23+H23 | J23: รอข้อมูล | K23: รอเอกสารออกแบบเหล็กเสริม (อ้างอิงประมาณ 160 กก./ลบ.ม. ≈ 11,000 กก.)
A24: 2.4 | B24: หมวดงานพื้น คสล.
A25: 2.4.1 | B25: พื้น S1 คสล. หนา 0.20 ม. วางบนเสาเข็ม TOP +0.50 พร้อมไม้แบบข้าง | C25: 3206.48 | D25: ตร.ม. | F25: =IF(C25="",0,C25*E25) | H25: =IF(C25="",0,C25*G25) | I25: =F25+H25 | J25: แก้ไข | K25: เดิม 3,240 → 3,206.48 ตร.ม. คอนกรีต 641.30 ลบ.ม. (S6.1)
A26: 2.4.2 | B26: พื้นห้อง SF02 หนา 0.25 / AF01 หนา 0.10 ระดับพื้นชั้น 1 | C26: 51.82 | D26: ตร.ม. | F26: =IF(C26="",0,C26*E26) | H26: =IF(C26="",0,C26*G26) | I26: =F26+H26 | J26: เพิ่มใหม่ | K26: เพิ่ม: SF02 30.50 + AF01 21.32 ตร.ม. คอนกรีต 9.76 ลบ.ม. (S6.1)
A27: 2.4.3 | B27: เหล็กเสริม/ตะแกรงเหล็ก พื้น S1, SF02, AF01 | D27: กก. | F27: =IF(C27="",0,C27*E27) | H27: =IF(C27="",0,C27*G27) | I27: =F27+H27 | J27: รอข้อมูล | K27: รอเอกสารออกแบบเหล็กเสริม (อ้างอิงประมาณ 80 กก./ลบ.ม. ≈ 52,000 กก.)
A28: 2.5 | B28: หมวดงานโครงสร้างเหล็ก (หน้าตัดโครงถัก แป ค้ำยัน รอแบบโครงหลังคา)
A29: 2.5.1 | B29: เสาเหล็ก H250x175x44.1 กก./ม. บนหัวเสา คสล. +4.50 ถึง +9.00 พร้อมแผ่นเหล็กฐาน Anchor bolt | C29: 9513 | D29: กก. | F29: =IF(C29="",0,C29*E29) | H29: =IF(C29="",0,C29*G29) | I29: =F29+H29 | J29: แก้ไข | K29: S4.1: 47 ต้น ยาว 215.72 ม.
A30: 2.5.2 | B30: โครงถักหลังคา ช่วง 2 x 30 ม. 10 แนว (กริด A-J) สันหลังคา +14.10 | C30: 25534 | D30: กก. | F30: =IF(C30="",0,C30*E30) | H30: =IF(C30="",0,C30*G30) | I30: =F30+H30 | J30: รอข้อมูล | K30: ประมาณการจากโมเดล (คอร์ด 2C-150x65x20x3.2, ค้ำ C-100x50x20x2.3) รอแบบ
A31: 2.5.3 | B31: แปหลังคา C-125x50x20x3.2 และแปผนัง (Girt) | C31: 20928 | D31: กก. | F31: =IF(C31="",0,C31*E31) | H31: =IF(C31="",0,C31*G31) | I31: =F31+H31 | J31: รอข้อมูล | K31: ประมาณการจากโมเดล แปหลังคา ~2,730 ม. + แปผนัง 684 ม. รอแบบ
A32: 2.5.4 | B32: ค้ำยันหลังคา/ผนัง RB12 + Turnbuckle, Sag rod, แผ่นต่อ สลักเกลียว (จุดต่อ ~10%) | C32: 7100 | D32: กก. | F32: =IF(C32="",0,C32*E32) | H32: =IF(C32="",0,C32*G32) | I32: =F32+H32 | J32: รอข้อมูล | K32: ประมาณการ รอแบบ
A33: 2.5.5 | B33: ทาสีกันสนิม 2 เที่ยว + สีทับหน้า 1 เที่ยว โครงสร้างเหล็กทั้งหมด | C33: 1 | D33: เหมา | F33: =IF(C33="",0,C33*E33) | H33: =IF(C33="",0,C33*G33) | I33: =F33+H33 | J33: เพิ่มใหม่
A34: 2.6 | B34: หมวดงานชั้นลอย F8 (ระดับ +3.30)
A35: 2.6.1 | B35: เสาเหล็กชั้นลอย H250x250x66.5 กก./ม. | C35: 6703 | D35: กก. | F35: =IF(C35="",0,C35*E35) | H35: =IF(C35="",0,C35*G35) | I35: =F35+H35 | J35: เพิ่มใหม่ | K35: เพิ่ม: S4.1 36 ต้น ยาว 100.80 ม.
A36: 2.6.2 | B36: คานเหล็กชั้นลอย (หน้าตัดรอแบบ) | C36: 5219 | D36: กก. | F36: =IF(C36="",0,C36*E36) | H36: =IF(C36="",0,C36*G36) | I36: =F36+H36 | J36: รอข้อมูล | K36: เพิ่ม: ประมาณการ H200x100 ตารางคาน 3.00 ม.
A37: 2.6.3 | B37: พื้นชั้นลอย F8 (Metal deck/พื้นสำเร็จ ตามแบบ) | C37: 306.15 | D37: ตร.ม. | F37: =IF(C37="",0,C37*E37) | H37: =IF(C37="",0,C37*G37) | I37: =F37+H37 | J37: เพิ่มใหม่ | K37: เพิ่ม: S6.1 306.15 ตร.ม.
A38: 2.6.4 | B38: บันไดเหล็กขึ้นชั้นลอย กว้าง ~1.40 ม. พร้อมราวกันตก | C38: 1 | D38: ชุด | F38: =IF(C38="",0,C38*E38) | H38: =IF(C38="",0,C38*G38) | I38: =F38+H38 | J38: เพิ่มใหม่ | K38: เพิ่ม: ตำแหน่ง DN แนวกริด D
B39: รวมหมวดที่ 2 งานโครงสร้าง | F39: =SUM(F5:F38) | H39: =SUM(H5:H38) | I39: =SUM(I5:I38)
B40: หมายเหตุ: ช่องสีเหลืองสำหรับกรอกราคาต่อหน่วย | สีแดง = เพิ่มใหม่ | สีส้ม = แก้ไขปริมาณ/รายละเอียด | สีม่วง = รอข้อมูล/ยืนยันจากผู้ออกแบบ

Sheet 3-งานสถาปัตยกรรม
A1: บัญชีปริมาณงานและราคา หมวดที่ 3 งานสถาปัตยกรรม
A2: งานก่อสร้างอาคารโกดังและงานบริเวณ บริษัท ตงเฉิน อีเล็คทริค เคเบิ้ล แอนด์ไวร์ จำกัด
A3: สถานที่: เลขที่ 10/7 หมู่ที่ 5 ตำบลท่าข้าม อำเภอสามพราน จังหวัดนครปฐม 73110 | อ้างอิงแบบ S201, S201-B, S202, A101, A202 (Issue 01/09/69) | ฉบับแก้ไข v2 (ทวนสอบแบบ + BIM) 27/10/2569
A4: ลำดับ | B4: รายการ | C4: ปริมาณ | D4: หน่วย | E4: ค่าวัสดุ/หน่วย | F4: ค่าวัสดุรวม | G4: ค่าแรง/หน่วย | H4: ค่าแรงรวม | I4: รวมเป็นเงิน | J4: สถานะ | K4: หมายเหตุ / ที่มาของปริมาณ
A5: 3.1 | B5: หมวดงานหลังคาและผนังภายนอก
A6: 3.1.1 | B6: หลังคาเมทัลชีทหนา 0.47 มม. พร้อมฉนวน PU 25 มม. (พื้นที่ตามลาด) | C6: 3395 | D6: ตร.ม. | F6: =IF(C6="",0,C6*E6) | H6: =IF(C6="",0,C6*G6) | I6: =F6+H6 | J6: เพิ่มใหม่ | K6: เพิ่ม: จากโมเดล 2 ลาด 30.2 ม. x 55 ม. (สเปควัสดุรอยืนยัน)
A7: 3.1.2 | B7: Jack roof กว้าง 6.00 ม. ยาว 42.00 ม. สัน +15.25 พร้อมตะแกรงระบายอากาศ | C7: 252 | D7: ตร.ม. | F7: =IF(C7="",0,C7*E7) | H7: =IF(C7="",0,C7*G7) | I7: =F7+H7 | J7: เพิ่มใหม่ | K7: เพิ่ม: A202
A8: 3.1.3 | B8: ครอบสัน ครอบข้าง แผ่นปิดเชิงชาย Flashing | C8: 1 | D8: เหมา | F8: =IF(C8="",0,C8*E8) | H8: =IF(C8="",0,C8*G8) | I8: =F8+H8 | J8: เพิ่มใหม่ | K8: เพิ่ม
A9: 3.1.4 | B9: รางน้ำฝนเหล็กอาบสังกะสี 0.30x0.30 ม. | C9: 110 | D9: ม. | F9: =IF(C9="",0,C9*E9) | H9: =IF(C9="",0,C9*G9) | I9: =F9+H9 | J9: เพิ่มใหม่ | K9: เพิ่ม: ชายคาแนวกริด 1 และ 11
A10: 3.1.5 | B10: ท่อระบายน้ำฝน PVC Ø4" พร้อมอุปกรณ์ยึด | C10: 100 | D10: ม. | F10: =IF(C10="",0,C10*E10) | H10: =IF(C10="",0,C10*G10) | I10: =F10+H10 | J10: รอข้อมูล | K10: เพิ่ม: 10 จุด x 10 ม. (สมมติ)
A11: 3.1.6 | B11: ผนังเมทัลชีท ระดับ +5.20 ถึงชายคา/จั่ว | C11: 1379 | D11: ตร.ม. | F11: =IF(C11="",0,C11*E11) | H11: =IF(C11="",0,C11*G11) | I11: =F11+H11 | J11: เพิ่มใหม่ | K11: เพิ่ม: จากโมเดล ตาม A202
A12: 3.2 | B12: หมวดงานผนังก่ออิฐ ฉาบปูน และผนังกันไฟ (ถ้ามี)
A13: 3.2.1 | B13: ผนังก่ออิฐมวลเบา หนา 0.15 ม. +0.50 ถึง +4.50 พร้อมเสาเอ็น-ทับหลัง | C13: 868 | D13: ตร.ม. | F13: =IF(C13="",0,C13*E13) | H13: =IF(C13="",0,C13*G13) | I13: =F13+H13 | J13: รอข้อมูล | K13: เพิ่ม: สมมติตามรูปด้าน A202 ยังไม่มีแบบสถาปัตย์
A14: 3.2.2 | B14: ฉาบปูนผนัง 2 ด้าน | C14: 1736 | D14: ตร.ม. | F14: =IF(C14="",0,C14*E14) | H14: =IF(C14="",0,C14*G14) | I14: =F14+H14 | J14: รอข้อมูล | K14: เพิ่ม
A15: 3.3 | B15: หมวดงานผิวพื้น
A16: 3.3.1 | B16: พื้นขัดมันผสม Floor Hardener | C16: 3206.48 | D16: ตร.ม. | F16: =IF(C16="",0,C16*E16) | H16: =IF(C16="",0,C16*G16) | I16: =F16+H16 | J16: แก้ไข | K16: เดิม 3,240 → พื้นที่ S1 (S6.1)
A17: 3.4 | B17: หมวดงานประตู หน้าต่าง และประตูม้วน/ประตูเลื่อนขนส่ง
A18: 3.4.1 | B18: ประตูม้วนเหล็กไฟฟ้า ~6.00x4.00 ม. ทางลาดขนส่ง | C18: 2 | D18: ชุด | F18: =IF(C18="",0,C18*E18) | H18: =IF(C18="",0,C18*G18) | I18: =F18+H18 | J18: รอข้อมูล | K18: เพิ่ม: ตำแหน่งตาม A101 ขนาดรอยืนยัน
A19: 3.4.2 | B19: ประตู D1/D2/D4 และหน้าต่าง ตามแบบ A101 | C19: 1 | D19: เหมา | F19: =IF(C19="",0,C19*E19) | H19: =IF(C19="",0,C19*G19) | I19: =F19+H19 | J19: รอข้อมูล | K19: เพิ่ม: รอตารางประตู-หน้าต่าง
A20: 3.5 | B20: หมวดงานฝ้าและงานทาสี
A21: 3.5.1 | B21: ทาสีผนังภายใน-ภายนอก (รองพื้น + ทับหน้า 2 เที่ยว) | C21: 1736 | D21: ตร.ม. | F21: =IF(C21="",0,C21*E21) | H21: =IF(C21="",0,C21*G21) | I21: =F21+H21 | J21: รอข้อมูล | K21: เพิ่ม
A22: 3.6 | B22: หมวดงานสถาปัตยกรรมอาคารประกอบ
A23: 3.6.1 | B23: ห้อง MDB 17.79 ตร.ม. (ผนัง ประตูกันไฟ พื้น ฝ้า) | C23: 1 | D23: ห้อง | F23: =IF(C23="",0,C23*E23) | H23: =IF(C23="",0,C23*G23) | I23: =F23+H23 | J23: เพิ่มใหม่ | K23: เพิ่ม: A101
A24: 3.6.2 | B24: ห้องเก็บสารเคมี (Chemical Drum Storage) 21.84 ตร.ม. พร้อมขอบกั้นรั่วไหล | C24: 1 | D24: ห้อง | F24: =IF(C24="",0,C24*E24) | H24: =IF(C24="",0,C24*G24) | I24: =F24+H24 | J24: เพิ่มใหม่ | K24: เพิ่ม: A101
A25: 3.6.3 | B25: อาคารห้องน้ำ 2.40 x 8.00 ม. (สุขภัณฑ์ กระเบื้อง ระบบสุขาภิบาลภายใน) | C25: 1 | D25: หลัง | F25: =IF(C25="",0,C25*E25) | H25: =IF(C25="",0,C25*G25) | I25: =F25+H25 | J25: รอข้อมูล | K25: เพิ่ม: A101/S201 รอแบบสถาปัตย์
A26: 3.6.4 | B26: ห้องประกอบแนวกริด A (กริด 8-10) | C26: 1 | D26: เหมา | F26: =IF(C26="",0,C26*E26) | H26: =IF(C26="",0,C26*G26) | I26: =F26+H26 | J26: รอข้อมูล | K26: เพิ่ม: เห็นในผัง A101 รอแบบ
B27: รวมหมวดที่ 3 งานสถาปัตยกรรม | F27: =SUM(F5:F26) | H27: =SUM(H5:H26) | I27: =SUM(I5:I26)
B28: หมายเหตุ: ช่องสีเหลืองสำหรับกรอกราคาต่อหน่วย | สีแดง = เพิ่มใหม่ | สีส้ม = แก้ไขปริมาณ/รายละเอียด | สีม่วง = รอข้อมูล/ยืนยันจากผู้ออกแบบ

Sheet 4-งานบริเวณ
A1: บัญชีปริมาณงานและราคา หมวดที่ 4 งานบริเวณ (เพิ่มใหม่ทั้งหมวด)
A2: งานก่อสร้างอาคารโกดังและงานบริเวณ บริษัท ตงเฉิน อีเล็คทริค เคเบิ้ล แอนด์ไวร์ จำกัด
A3: สถานที่: เลขที่ 10/7 หมู่ที่ 5 ตำบลท่าข้าม อำเภอสามพราน จังหวัดนครปฐม 73110 | อ้างอิงแบบ S201, S201-B, S202, A101, A202 (Issue 01/09/69) | ฉบับแก้ไข v2 (ทวนสอบแบบ + BIM) 27/10/2569
A4: ลำดับ | B4: รายการ | C4: ปริมาณ | D4: หน่วย | E4: ค่าวัสดุ/หน่วย | F4: ค่าวัสดุรวม | G4: ค่าแรง/หน่วย | H4: ค่าแรงรวม | I4: รวมเป็นเงิน | J4: สถานะ | K4: หมายเหตุ / ที่มาของปริมาณ
A5: 4.1 | B5: หมวดงานพื้นถนนรอบอาคาร
A6: 4.1.1 | B6: เสาเข็มตอก I-220x220 ยาว 22 ม. รับพื้นถนนรอบอาคาร (I22-22) รวมค่าตอก | C6: 249 | D6: ต้น | F6: =IF(C6="",0,C6*E6) | H6: =IF(C6="",0,C6*G6) | I6: =F6+H6 | J6: เพิ่มใหม่ | K6: ตาราง S2 = 249; นับจากผัง S201 ได้ 232 (ยืนยันจำนวน)
A7: 4.1.2 | B7: ฐาน F1A 0.60x0.60x0.30 ม. รับพื้นถนน | C7: 249 | D7: ฐาน | F7: =IF(C7="",0,C7*E7) | H7: =IF(C7="",0,C7*G7) | I7: =F7+H7 | J7: เพิ่มใหม่ | K7: คอนกรีต 26.78, ทราย 35.86, คอนกรีตหยาบ 6.10 ลบ.ม. (S1.1)
A8: 4.1.3 | B8: พื้นถนน S2 คสล. หนา 0.15 ม. TOP ±0.00 พร้อมรอยต่อ/ตัดรอยต่อ | C8: 2440.69 | D8: ตร.ม. | F8: =IF(C8="",0,C8*E8) | H8: =IF(C8="",0,C8*G8) | I8: =F8+H8 | J8: เพิ่มใหม่ | K8: คอนกรีต 366.10 ลบ.ม. (S6.1)
A9: 4.1.4 | B9: พื้น AF01 / SF02 ระดับถนน | C9: 110.14 | D9: ตร.ม. | F9: =IF(C9="",0,C9*E9) | H9: =IF(C9="",0,C9*G9) | I9: =F9+H9 | J9: เพิ่มใหม่ | K9: AF01 16.88 + SF02 93.26 ตร.ม. คอนกรีต 25.76 ลบ.ม. (S6.1)
A10: 4.1.5 | B10: เหล็กเสริม/ตะแกรงเหล็ก พื้นถนน และฐาน F1A | D10: กก. | F10: =IF(C10="",0,C10*E10) | H10: =IF(C10="",0,C10*G10) | I10: =F10+H10 | J10: รอข้อมูล | K10: รอเอกสารออกแบบเหล็กเสริม
A11: 4.2 | B11: หมวดงานทางลาดขนส่ง
A12: 4.2.1 | B12: ทางลาดขนส่ง คสล. กว้าง 6.00 ม. (ด้านเหนือแนวกริด 5-6 และด้านใต้แนวกริด 7-8) | C12: 2 | D12: แห่ง | F12: =IF(C12="",0,C12*E12) | H12: =IF(C12="",0,C12*G12) | I12: =F12+H12 | J12: เพิ่มใหม่ | K12: A101/S202 ขนาดวัดจากผัง
A13: 4.3 | B13: หมวดงานฐานหม้อแปลง
A14: 4.3.1 | B14: เสาเข็มตอก I-220x220 ยาว 22 ม. รับฐานหม้อแปลง (I22-TR) รวมค่าตอก | C14: 6 | D14: ต้น | F14: =IF(C14="",0,C14*E14) | H14: =IF(C14="",0,C14*G14) | I14: =F14+H14 | J14: เพิ่มใหม่ | K14: S2 / S201
A15: 4.3.2 | B15: ฐานหม้อแปลง คสล. (ขนาดรอแบบขยาย) | C15: 1 | D15: ชุด | F15: =IF(C15="",0,C15*E15) | H15: =IF(C15="",0,C15*G15) | I15: =F15+H15 | J15: รอข้อมูล
A16: 4.4 | B16: หมวดงานถังเก็บน้ำใต้ดิน
A17: 4.4.1 | B17: ถังเก็บน้ำใต้ดิน คสล. ~12.1 x 6.6 ม. พื้นหนา 0.25 ม. (TF -2.60 / BF -2.85) ผนัง ฝา บ่อพัก กันซึม | C17: 1 | D17: ชุด | F17: =IF(C17="",0,C17*E17) | H17: =IF(C17="",0,C17*G17) | I17: =F17+H17 | J17: รอข้อมูล | K17: S202 ผนัง/ฝารอแบบขยาย
A18: 4.5 | B18: หมวดงานระบายน้ำ
A19: 4.5.1 | B19: รางระบายน้ำ คสล. พร้อมฝาปิด ตามแนวเขตที่ดิน | C19: 302 | D19: ม. | F19: =IF(C19="",0,C19*E19) | H19: =IF(C19="",0,C19*G19) | I19: =F19+H19 | J19: รอข้อมูล | K19: A101 ขนาดรางรอแบบขยาย
A20: 4.5.2 | B20: บ่อพัก/บ่อบำบัด และจุดเชื่อมท่อระบายสาธารณะ | C20: 1 | D20: เหมา | F20: =IF(C20="",0,C20*E20) | H20: =IF(C20="",0,C20*G20) | I20: =F20+H20 | J20: รอข้อมูล | K20: รอแบบ
A21: 4.6 | B21: หมวดงานที่ต้องยืนยันขอบเขต
A22: 4.6.1 | B22: เสาเข็ม I-260x260 + ฐาน 0.66x0.66 ม. แนวเขตที่ดินด้านใต้และตะวันออก (ไม่มีใน BOQ/ตาราง S2) | C22: 16 | D22: ชุด | F22: =IF(C22="",0,C22*E22) | H22: =IF(C22="",0,C22*G22) | I22: =F22+H22 | J22: รอข้อมูล | K22: พบในผัง S201 16 จุด ยังไม่ทราบหน้าที่ (เสารั้ว/เสาไฟ/ป้าย?) สอบถามผู้ออกแบบ
A23: 4.6.2 | B23: รั้วถาวร / ประตูทางเข้าโครงการ | D23: ม. | F23: =IF(C23="",0,C23*E23) | H23: =IF(C23="",0,C23*G23) | I23: =F23+H23 | J23: รอข้อมูล | K23: ไม่มีในแบบ ยืนยันว่าอยู่ในขอบเขตหรือไม่
B24: รวมหมวดที่ 4 งานบริเวณ (เพิ่มใหม่ทั้งหมวด) | F24: =SUM(F5:F23) | H24: =SUM(H5:H23) | I24: =SUM(I5:I23)
B25: หมายเหตุ: ช่องสีเหลืองสำหรับกรอกราคาต่อหน่วย | สีแดง = เพิ่มใหม่ | สีส้ม = แก้ไขปริมาณ/รายละเอียด | สีม่วง = รอข้อมูล/ยืนยันจากผู้ออกแบบ

Sheet บันทึกการแก้ไข
A1: บันทึกการแก้ไข BOQ v2 และข้อสังเกตจากการทวนสอบแบบ/โมเดล BIM
A2: ลำดับ | B2: สถานะ | C2: รายการ | D2: หมายเหตุ
A3: 1.1.2 | B3: แก้ไข | C3: วางตำแหน่งเสาเข็มด้วยกล้องสำรวจ (Total Station) และตรวจสอบตำแหน่งหลังตอก | D3: เดิม 470 → นับจากผัง S201 ทุกชนิด (ดูหมวด 2.1 และ 4.1)
A4: 1.2.1 | B4: แก้ไข | C4: รั้วชั่วคราวแผ่นเหล็กรีดลอน (Metal Sheet) สูง 2.00 ม. โครงเหล็กกล่อง พร้อมทาสี | D4: เดิม 308 (สมมติ 80x74) → เส้นรอบแนวเขตที่ดินจากผัง S202
A5: 1.2.4 | B5: แก้ไข | C5: โรงเก็บวัสดุและเครื่องมือ (Store) พร้อมลานกองเหล็กเสริมและลานดัดเหล็ก | D5: พื้นที่ว่างรอบอาคารแคบ (4-14 ม.) ต้องย้ายออกก่อนงานพื้นถนน หรือเช่าพื้นที่ข้างเคียง
A6: 1.3.1 | B6: แก้ไข | C6: ถมดินปรับระดับ บดอัดเป็นชั้นหนาไม่เกิน 0.20 ม. ความแน่นไม่น้อยกว่า 95% Standard Proctor | D6: เดิม 1,856 (ถมเฉลี่ย 0.50 ม.) → A202: ถนนอ้างอิง -1.50 / ถนนรอบอาคาร ±0.00 / FFL +0.50 ถ้าดินเดิม -1.50 = 8,566; -1.00 = 5,593; -0.50 = 2,620 ลบ.ม. ยืนยันด้วยผลสำรวจระดับ P1.2 และเสนอราคาต่อ ลบ.ม.
A7: 1.3.4 | B7: เพิ่มใหม่ | C7: ขุดดินฐานรากและขนย้ายดินส่วนเกิน (จากตาราง S1.1) | D7: S201-B ตาราง S1.1 รวม F1/F1A/F1P/F2P (ไม่รวมถังใต้ดิน 4.4)
A8: 1.3.5 | B8: เพิ่มใหม่ | C8: ป้องกันดินพังและสูบน้ำ งานขุดถังเก็บน้ำใต้ดิน ลึก ~3.0 ม. (Sheet pile/ค้ำยัน) | D8: ระดับก้นถัง BF -2.85 (S202)
A9: 1.4.2 | B9: แก้ไข | C9: ทดสอบกำลังรับน้ำหนักเสาเข็มแบบพลศาสตร์ (Dynamic Load Test) | D9: เดิม 2 → อย่างน้อย 1 ต้นต่อขนาดเข็ม (I22/I26/I35) หรือตามวิศวกรกำหนด
A10: 1.4.3 | B10: แก้ไข | C10: ทดสอบความแน่นดินถมในสนาม (Field Density Test) | D10: เดิม 6 → พื้นที่ 5,946 ตร.ม. ÷ 500 = 12 จุด/ชั้น x 8 ชั้น (ถม 1.60 ม. ชั้นละ 0.20)
A11: 2.1.2 | B11: แก้ไข | C11: เสาเข็มตอก I-350x350 ยาว 22 ม. รับพื้นโรงงาน (I35-22) ระยะ 3.00x3.00 ม. รวมค่าตอก | D11: ตรงกัน 360 ต้น; ระบุขนาด 350 มม. (ราคาต่างจากเข็มฐานราก)
A12: 2.1.3 | B12: แก้ไข | C12: เสาเข็มตอก I-260x260 ยาว 22 ม. อาคารประกอบ ฐาน F1P-1 (ห้องน้ำ 6, ห้องสารเคมี 3, ทางลาดเหนือ 2) รวมค่าตอก | D12: เดิม 18 → 11 (นับจาก S201)
A13: 2.1.4 | B13: เพิ่มใหม่ | C13: เสาเข็มตอก I-260x260 รับถังเก็บน้ำใต้ดิน (ตัดหัวลดระดับ 1 ม.) รวมค่าตอก | D13: เพิ่ม: S201-B (I26) นับจากผังได้ 17
... A32: 2.5.4 | B32: รอข้อมูล | C32: ค้ำยันหลังคา/ผนัง RB12 + Turnbuckle, Sag rod, แผ่นต่อ สลักเกลียว (จุดต่อ ~10%) | D32: ประมาณการ รอแบบ
A33: 2.5.5 | B33: เพิ่มใหม่ | C33: ทาสีกันสนิม 2 เที่ยว + สีทับหน้า 1 เที่ยว โครงสร้างเหล็กทั้งหมด
A34: 2.6.1 | B34: เพิ่มใหม่ | C34: เสาเหล็กชั้นลอย H250x250x66.5 กก./ม. | D34: เพิ่ม: S4.1 36 ต้น ยาว 100.80 ม.
A35: 2.6.2 | B35: รอข้อมูล | C35: คานเหล็กชั้นลอย (หน้าตัดรอแบบ) | D35: เพิ่ม: ประมาณการ H200x100 ตารางคาน 3.00 ม.
A36: 2.6.3 | B36: เพิ่มใหม่ | C36: พื้นชั้นลอย F8 (Metal deck/พื้นสำเร็จ ตามแบบ) | D36: เพิ่ม: S6.1 306.15 ตร.ม.
A37: 2.6.4 | B37: เพิ่มใหม่ | C37: บันไดเหล็กขึ้นชั้นลอย กว้าง ~1.40 ม. พร้อมราวกันตก | D37: เพิ่ม: ตำแหน่ง DN แนวกริด D
A38: 3.1.1 | B38: เพิ่มใหม่ | C38: หลังคาเมทัลชีทหนา 0.47 มม. พร้อมฉนวน PU 25 มม. (พื้นที่ตามลาด) | D38: เพิ่ม: จากโมเดล 2 ลาด 30.2 ม. x 55 ม. (สเปควัสดุรอยืนยัน)
A39: 3.1.2 | B39: เพิ่มใหม่ | C39: Jack roof กว้าง 6.00 ม. ยาว 42.00 ม. สัน +15.25 พร้อมตะแกรงระบายอากาศ | D39: เพิ่ม: A202
A40: 3.1.3 | B40: เพิ่มใหม่ | C40: ครอบสัน ครอบข้าง แผ่นปิดเชิงชาย Flashing | D40: เพิ่ม
A41: 3.1.4 | B41: เพิ่มใหม่ | C41: รางน้ำฝนเหล็กอาบสังกะสี 0.30x0.30 ม. | D41: เพิ่ม: ชายคาแนวกริด 1 และ 11
A42: 3.1.5 | B42: รอข้อมูล | C42: ท่อระบายน้ำฝน PVC Ø4" พร้อมอุปกรณ์ยึด | D42: เพิ่ม: 10 จุด x 10 ม. (สมมติ)
A43: 3.1.6 | B43: เพิ่มใหม่ | C43: ผนังเมทัลชีท ระดับ +5.20 ถึงชายคา/จั่ว | D43: เพิ่ม: จากโมเดล ตาม A202
A44: 3.2.1 | B44: รอข้อมูล | C44: ผนังก่ออิฐมวลเบา หนา 0.15 ม. +0.50 ถึง +4.50 พร้อมเสาเอ็น-ทับหลัง | D44: เพิ่ม: สมมติตามรูปด้าน A202 ยังไม่มีแบบสถาปัตย์
A45: 3.2.2 | B45: รอข้อมูล | C45: ฉาบปูนผนัง 2 ด้าน | D45: เพิ่ม
... A60: 4.3.1 | B60: เพิ่มใหม่ | C60: เสาเข็มตอก I-220x220 ยาว 22 ม. รับฐานหม้อแปลง (I22-TR) รวมค่าตอก | D60: S2 / S201
A61: 4.3.2 | B61: รอข้อมูล | C61: ฐานหม้อแปลง คสล. (ขนาดรอแบบขยาย)
A62: 4.4.1 | B62: รอข้อมูล | C62: ถังเก็บน้ำใต้ดิน คสล. ~12.1 x 6.6 ม. พื้นหนา 0.25 ม. (TF -2.60 / BF -2.85) ผนัง ฝา บ่อพัก กันซึม | D62: S202 ผนัง/ฝารอแบบขยาย
A63: 4.5.1 | B63: รอข้อมูล | C63: รางระบายน้ำ คสล. พร้อมฝาปิด ตามแนวเขตที่ดิน | D63: A101 ขนาดรางรอแบบขยาย
A64: 4.5.2 | B64: รอข้อมูล | C64: บ่อพัก/บ่อบำบัด และจุดเชื่อมท่อระบายสาธารณะ | D64: รอแบบ
A65: 4.6.1 | B65: รอข้อมูล | C65: เสาเข็ม I-260x260 + ฐาน 0.66x0.66 ม. แนวเขตที่ดินด้านใต้และตะวันออก (ไม่มีใน BOQ/ตาราง S2) | D65: พบในผัง S201 16 จุด ยังไม่ทราบหน้าที่ (เสารั้ว/เสาไฟ/ป้าย?) สอบถามผู้ออกแบบ
A66: 4.6.2 | B66: รอข้อมูล | C66: รั้วถาวร / ประตูทางเข้าโครงการ | D66: ไม่มีในแบบ ยืนยันว่าอยู่ในขอบเขตหรือไม่
B68: ข้อสังเกต
B69: ขอบเขต | C69: งานระบบไฟฟ้า ประปา สุขาภิบาล ดับเพลิง (MEP) ไม่มีแบบ และไม่รวมในราคานี้ ยกเว้นที่ระบุ
B70: แบบ | C70: กรอบชื่อแบบทุกแผ่นระบุ 'แบบก่อสร้างบ้านพักอาศัย คสล 1 ชั้น' และ Date 03/31/22 ควรแก้ก่อนแนบประกอบใบเสนอราคา
B71: แบบ | C71: แบบไม่มีลูกศรทิศเหนือ (North arrow) ต้องระบุเพื่อวางทิศอาคารบนที่ดินจริง
B72: แบบ | C72: ตาราง S2 นับเข็ม 737 ต้น แต่ผัง S201 นับได้ 734 ต้น (+16 ต้นใต้ฐาน 0.66 ม. ที่ไม่อยู่ในตาราง) และ F2P ตารางนับ 47 แต่ผัง/ปริมาตร = 46
B73: เหล็กเสริม | C73: เหล็กเสริม คสล. ทุกรายการรอเอกสารการออกแบบเหล็กเสริมจากผู้ออกแบบ ตัวเลขในหมายเหตุเป็นค่าอ้างอิงเท่านั้น ไม่ใช้เป็นปริมาณ
...
