Workbook

Sheet สรุป
A1: สรุปตารางโครงสร้าง ฐานราก เสา คาน รายจุด
A2: งานก่อสร้างอาคารโกดังและงานบริเวณ บริษัท ตงเฉิน อีเล็คทริค เคเบิ้ล แอนด์ไวร์ จำกัด | WEC-TC-6901
A3: กลุ่ม | B3: ชนิด | C3: จำนวน | D3: คอนกรีต (ลบ.ม.) | E3: ไม้แบบ (ตร.ม.) | F3: เหล็กเสริม (กก.) | G3: เทียบรายการ BOQ v2
A4: ฐานราก | B4: F2P | C4: =COUNTIF('1-ฐานราก รายจุด'!B:B,B4) | D4: =SUMIF('1-ฐานราก รายจุด'!B:B,B4,'1-ฐานราก รายจุด'!O:O) | E4: =SUMIF('1-ฐานราก รายจุด'!B:B,B4,'1-ฐานราก รายจุด'!P:P) | F4: =SUMIF('1-ฐานราก รายจุด'!B:B,B4,'1-ฐานราก รายจุด'!T:T) | G4: 2.2.1
A5: ฐานราก | B5: F1P | C5: =COUNTIF('1-ฐานราก รายจุด'!B:B,B5) | D5: =SUMIF('1-ฐานราก รายจุด'!B:B,B5,'1-ฐานราก รายจุด'!O:O) | E5: =SUMIF('1-ฐานราก รายจุด'!B:B,B5,'1-ฐานราก รายจุด'!P:P) | F5: =SUMIF('1-ฐานราก รายจุด'!B:B,B5,'1-ฐานราก รายจุด'!T:T) | G5: 2.2.2
A6: ฐานราก | B6: F1P-1 | C6: =COUNTIF('1-ฐานราก รายจุด'!B:B,B6) | D6: =SUMIF('1-ฐานราก รายจุด'!B:B,B6,'1-ฐานราก รายจุด'!O:O) | E6: =SUMIF('1-ฐานราก รายจุด'!B:B,B6,'1-ฐานราก รายจุด'!P:P) | F6: =SUMIF('1-ฐานราก รายจุด'!B:B,B6,'1-ฐานราก รายจุด'!T:T) | G6: 2.2.3
A7: ฐานราก | B7: F1A | C7: =COUNTIF('1-ฐานราก รายจุด'!B:B,B7) | D7: =SUMIF('1-ฐานราก รายจุด'!B:B,B7,'1-ฐานราก รายจุด'!O:O) | E7: =SUMIF('1-ฐานราก รายจุด'!B:B,B7,'1-ฐานราก รายจุด'!P:P) | F7: =SUMIF('1-ฐานราก รายจุด'!B:B,B7,'1-ฐานราก รายจุด'!T:T) | G7: 4.1.2
A8: ฐานราก | B8: SQ66 | C8: =COUNTIF('1-ฐานราก รายจุด'!B:B,B8) | D8: =SUMIF('1-ฐานราก รายจุด'!B:B,B8,'1-ฐานราก รายจุด'!O:O) | E8: =SUMIF('1-ฐานราก รายจุด'!B:B,B8,'1-ฐานราก รายจุด'!P:P) | F8: =SUMIF('1-ฐานราก รายจุด'!B:B,B8,'1-ฐานราก รายจุด'!T:T) | G8: 4.6.1
A9: ฐานราก | B9: TRP | C9: =COUNTIF('1-ฐานราก รายจุด'!B:B,B9) | D9: =SUMIF('1-ฐานราก รายจุด'!B:B,B9,'1-ฐานราก รายจุด'!O:O) | E9: =SUMIF('1-ฐานราก รายจุด'!B:B,B9,'1-ฐานราก รายจุด'!P:P) | F9: =SUMIF('1-ฐานราก รายจุด'!B:B,B9,'1-ฐานราก รายจุด'!T:T) | G9: 4.3.2
A10: เสา | B10: C1 | C10: =COUNTIF('3-เสา รายต้น'!B:B,B10) | D10: =SUMIF('3-เสา รายต้น'!B:B,B10,'3-เสา รายต้น'!L:L) | E10: =SUMIF('3-เสา รายต้น'!B:B,B10,'3-เสา รายต้น'!M:M) | F10: =SUMIF('3-เสา รายต้น'!B:B,B10,'3-เสา รายต้น'!N:N) | G10: 2.3.1
A11: เสา | B11: C2 | C11: =COUNTIF('3-เสา รายต้น'!B:B,B11) | D11: =SUMIF('3-เสา รายต้น'!B:B,B11,'3-เสา รายต้น'!L:L) | E11: =SUMIF('3-เสา รายต้น'!B:B,B11,'3-เสา รายต้น'!M:M) | F11: =SUMIF('3-เสา รายต้น'!B:B,B11,'3-เสา รายต้น'!N:N) | G11: 2.3.2
A12: เสา | B12: C3 | C12: =COUNTIF('3-เสา รายต้น'!B:B,B12) | D12: =SUMIF('3-เสา รายต้น'!B:B,B12,'3-เสา รายต้น'!L:L) | E12: =SUMIF('3-เสา รายต้น'!B:B,B12,'3-เสา รายต้น'!M:M) | F12: =SUMIF('3-เสา รายต้น'!B:B,B12,'3-เสา รายต้น'!N:N) | G12: 2.3.3
A13: เสา | B13: SC | C13: =COUNTIF('3-เสา รายต้น'!B:B,B13) | D13: =SUMIF('3-เสา รายต้น'!B:B,B13,'3-เสา รายต้น'!L:L) | E13: =SUMIF('3-เสา รายต้น'!B:B,B13,'3-เสา รายต้น'!M:M) | F13: =SUMIF('3-เสา รายต้น'!B:B,B13,'3-เสา รายต้น'!N:N) | G13: 3.2.5
A14: คาน | B14: B1 | C14: =COUNTIF('5-คาน รายช่วง'!B:B,B14) | D14: =SUMIF('5-คาน รายช่วง'!B:B,B14,'5-คาน รายช่วง'!L:L) | E14: =SUMIF('5-คาน รายช่วง'!B:B,B14,'5-คาน รายช่วง'!M:M) | F14: =SUMIF('5-คาน รายช่วง'!B:B,B14,'5-คาน รายช่วง'!S:S) | G14: 2.3.4
A15: คาน | B15: B3 | C15: =COUNTIF('5-คาน รายช่วง'!B:B,B15) | D15: =SUMIF('5-คาน รายช่วง'!B:B,B15,'5-คาน รายช่วง'!L:L) | E15: =SUMIF('5-คาน รายช่วง'!B:B,B15,'5-คาน รายช่วง'!M:M) | F15: =SUMIF('5-คาน รายช่วง'!B:B,B15,'5-คาน รายช่วง'!S:S) | G15: 2.3.5
A16: คาน | B16: LB | C16: =COUNTIF('5-คาน รายช่วง'!B:B,B16) | D16: =SUMIF('5-คาน รายช่วง'!B:B,B16,'5-คาน รายช่วง'!L:L) | E16: =SUMIF('5-คาน รายช่วง'!B:B,B16,'5-คาน รายช่วง'!M:M) | F16: =SUMIF('5-คาน รายช่วง'!B:B,B16,'5-คาน รายช่วง'!S:S) | G16: 3.2.3
A17: คาน | B17: TB | C17: =COUNTIF('5-คาน รายช่วง'!B:B,B17) | D17: =SUMIF('5-คาน รายช่วง'!B:B,B17,'5-คาน รายช่วง'!L:L) | E17: =SUMIF('5-คาน รายช่วง'!B:B,B17,'5-คาน รายช่วง'!M:M) | F17: =SUMIF('5-คาน รายช่วง'!B:B,B17,'5-คาน รายช่วง'!S:S) | G17: 3.2.4
A18: รวม | C18: =SUM(C4:C17) | D18: =SUM(D4:D17) | E18: =SUM(E4:E17) | F18: =SUM(F4:F17)
A20: วิธีใช้: กรอกเหล็กเสริมในชีต 2 (ฐานราก), 4 (เสา), 6 (คาน) ตามเอกสารออกแบบ แล้วน้ำหนักเหล็กทุกจุดในชีต 1, 3, 5 และสรุปนี้คำนวณใหม่ทันที; รหัสชิ้นส่วนตรงกับโมเดล 3D (คลิกชิ้นส่วนเพื่อดูรหัส) และ Pset_TC_BOQ_4D ใน IFC

Sheet 1-ฐานราก รายจุด
A1: ตารางฐานรากรายจุด: ขนาด ระดับ ความลึก เข็ม และปริมาณ (เหล็กเสริมคำนวณจากชีต 2)
A2: งานก่อสร้างอาคารโกดังและงานบริเวณ บริษัท ตงเฉิน อีเล็คทริค เคเบิ้ล แอนด์ไวร์ จำกัด | WEC-TC-6901
A3: รหัส | B3: ชนิด | C3: ตำแหน่งกริด | D3: พิกัด x (ม.) | E3: พิกัด y (ม.) | F3: กว้าง X (ม.) | G3: ยาว Y (ม.) | H3: หนา (ม.) | I3: ระดับหลังฐาน | J3: ระดับท้องฐาน | K3: ระดับก้นหลุม (หัก คสล.หยาบ+ทราย) | L3: ความลึกขุดจาก ±0.00 (ม.) | M3: เข็ม (ต้น) | N3: ชนิดเข็ม | O3: คอนกรีต (ลบ.ม.) | P3: ไม้แบบ (ตร.ม.) | Q3: ดินขุด (ลบ.ม.) | R3: ทรายรองพื้น (ลบ.ม.) | S3: คอนกรีตหยาบ (ลบ.ม.) | T3: เหล็กเสริม (กก.) | U3: กิจกรรม 4D | V3: สถานะ
A4: F2P-001 | B4: F2P | C4: 1/A | D4: -0.009 | E4: 0.008 | F4: 1.5 | G4: 0.6 | H4: 0.8 | I4: -0.4 | J4: -1.2 | K4: -1.35 | L4: 1.35 | M4: 2 | N4: 2x I-260 ยาว 22 ม. | O4: =F4*G4*H4 | P4: =2*(F4+G4)*H4 | Q4: =IF(L4>0,(F4+2*0.1)*(G4+2*0.1)*L4,0) | R4: =(F4+0.2)*(G4+0.2)*0.1 | S4: =(F4+0.2)*(G4+0.2)*0.05 | T4: =INDEX('2-ฐานราก เหล็กเสริม'!$S:$S,MATCH(B4,'2-ฐานราก เหล็กเสริม'!$A:$A,0)) | U4: M22 | V4: แบบ S201 (ตำแหน่ง) / ระดับรอยืนยัน
A5: F2P-002 | B5: F2P | C5: 2/A | D5: 5.988 | E5: 0.008 | F5: 0.6 | G5: 1.5 | H5: 0.8 | I5: -0.4 | J5: -1.2 | K5: -1.35 | L5: 1.35 | M5: 2 | N5: 2x I-260 ยาว 22 ม. | O5: =F5*G5*H5 | P5: =2*(F5+G5)*H5 | Q5: =IF(L5>0,(F5+2*0.1)*(G5+2*0.1)*L5,0) | R5: =(F5+0.2)*(G5+0.2)*0.1 | S5: =(F5+0.2)*(G5+0.2)*0.05 | T5: =INDEX('2-ฐานราก เหล็กเสริม'!$S:$S,MATCH(B5,'2-ฐานราก เหล็กเสริม'!$A:$A,0)) | U5: M22 | V5: แบบ S201 (ตำแหน่ง) / ระดับรอยืนยัน
A6: F2P-003 | B6: F2P | C6: 3/A | D6: 11.986 | E6: 0.008 | F6: 0.6 | G6: 1.5 | H6: 0.8 | I6: -0.4 | J6: -1.2 | K6: -1.35 | L6: 1.35 | M6: 2 | N6: 2x I-260 ยาว 22 ม. | O6: =F6*G6*H6 | P6: =2*(F6+G6)*H6 | Q6: =IF(L6>0,(F6+2*0.1)*(G6+2*0.1)*L6,0) | R6: =(F6+0.2)*(G6+0.2)*0.1 | S6: =(F6+0.2)*(G6+0.2)*0.05 | T6: =INDEX('2-ฐานราก เหล็กเสริม'!$S:$S,MATCH(B6,'2-ฐานราก เหล็กเสริม'!$A:$A,0)) | U6: M22 | V6: แบบ S201 (ตำแหน่ง) / ระดับรอยืนยัน
A7: F2P-004 | B7: F2P | C7: 4/A | D7: 17.99 | E7: 0.008 | F7: 0.6 | G7: 1.5 | H7: 0.8 | I7: -0.4 | J7: -1.2 | K7: -1.35 | L7: 1.35 | M7: 2 | N7: 2x I-260 ยาว 22 ม. | O7: =F7*G7*H7 | P7: =2*(F7+G7)*H7 | Q7: =IF(L7>0,(F7+2*0.1)*(G7+2*0.1)*L7,0) | R7: =(F7+0.2)*(G7+0.2)*0.1 | S7: =(F7+0.2)*(G7+0.2)*0.05 | T7: =INDEX('2-ฐานราก เหล็กเสริม'!$S:$S,MATCH(B7,'2-ฐานราก เหล็กเสริม'!$A:$A,0)) | U7: M22 | V7: แบบ S201 (ตำแหน่ง) / ระดับรอยืนยัน
A8: F2P-005 | B8: F2P | C8: 5/A | D8: 23.994 | E8: 0.008 | F8: 0.6 | G8: 1.5 | H8: 0.8 | I8: -0.4 | J8: -1.2 | K8: -1.35 | L8: 1.35 | M8: 2 | N8: 2x I-260 ยาว 22 ม. | O8: =F8*G8*H8 | P8: =2*(F8+G8)*H8 | Q8: =IF(L8>0,(F8+2*0.1)*(G8+2*0.1)*L8,0) | R8: =(F8+0.2)*(G8+0.2)*0.1 | S8: =(F8+0.2)*(G8+0.2)*0.05 | T8: =INDEX('2-ฐานราก เหล็กเสริม'!$S:$S,MATCH(B8,'2-ฐานราก เหล็กเสริม'!$A:$A,0)) | U8: M22 | V8: แบบ S201 (ตำแหน่ง) / ระดับรอยืนยัน
A9: F2P-006 | B9: F2P | C9: 6/A | D9: 29.992 | E9: 0.008 | F9: 1.5 | G9: 0.6 | H9: 0.8 | I9: -0.4 | J9: -1.2 | K9: -1.35 | L9: 1.35 | M9: 2 | N9: 2x I-260 ยาว 22 ม. | O9: =F9*G9*H9 | P9: =2*(F9+G9)*H9 | Q9: =IF(L9>0,(F9+2*0.1)*(G9+2*0.1)*L9,0) | R9: =(F9+0.2)*(G9+0.2)*0.1 | S9: =(F9+0.2)*(G9+0.2)*0.05 | T9: =INDEX('2-ฐานราก เหล็กเสริม'!$S:$S,MATCH(B9,'2-ฐานราก เหล็กเสริม'!$A:$A,0)) | U9: M22 | V9: แบบ S201 (ตำแหน่ง) / ระดับรอยืนยัน
A10: F2P-007 | B10: F2P | C10: 7/A | D10: 35.989 | E10: 0.008 | F10: 0.6 | G10: 1.5 | H10: 0.8 | I10: -0.4 | J10: -1.2 | K10: -1.35 | L10: 1.35 | M10: 2 | N10: 2x I-260 ยาว 22 ม. | O10: =F10*G10*H10 | P10: =2*(F10+G10)*H10 | Q10: =IF(L10>0,(F10+2*0.1)*(G10+2*0.1)*L10,0) | R10: =(F10+0.2)*(G10+0.2)*0.1 | S10: =(F10+0.2)*(G10+0.2)*0.05 | T10: =INDEX('2-ฐานราก เหล็กเสริม'!$S:$S,MATCH(B10,'2-ฐานราก เหล็กเสริม'!$A:$A,0)) | U10: M22 | V10: แบบ S201 (ตำแหน่ง) / ระดับรอยืนยัน
A11: F2P-008 | B11: F2P | C11: 8/A | D11: 41.987 | E11: 0.008 | F11: 0.6 | G11: 1.5 | H11: 0.8 | I11: -0.4 | J11: -1.2 | K11: -1.35 | L11: 1.35 | M11: 2 | N11: 2x I-260 ยาว 22 ม. | O11: =F11*G11*H11 | P11: =2*(F11+G11)*H11 | Q11: =IF(L11>0,(F11+2*0.1)*(G11+2*0.1)*L11,0) | R11: =(F11+0.2)*(G11+0.2)*0.1 | S11: =(F11+0.2)*(G11+0.2)*0.05 | T11: =INDEX('2-ฐานราก เหล็กเสริม'!$S:$S,MATCH(B11,'2-ฐานราก เหล็กเสริม'!$A:$A,0)) | U11: M22 | V11: แบบ S201 (ตำแหน่ง) / ระดับรอยืนยัน
A12: F2P-009 | B12: F2P | C12: 9/A | D12: 47.991 | E12: 0.008 | F12: 0.6 | G12: 1.5 | H12: 0.8 | I12: -0.4 | J12: -1.2 | K12: -1.35 | L12: 1.35 | M12: 2 | N12: 2x I-260 ยาว 22 ม. | O12: =F12*G12*H12 | P12: =2*(F12+G12)*H12 | Q12: =IF(L12>0,(F12+2*0.1)*(G12+2*0.1)*L12,0) | R12: =(F12+0.2)*(G12+0.2)*0.1 | S12: =(F12+0.2)*(G12+0.2)*0.05 | T12: =INDEX('2-ฐานราก เหล็กเสริม'!$S:$S,MATCH(B12,'2-ฐานราก เหล็กเสริม'!$A:$A,0)) | U12: M22 | V12: แบบ S201 (ตำแหน่ง) / ระดับรอยืนยัน
A13: F2P-010 | B13: F2P | C13: 10/A | D13: 53.995 | E13: 0.008 | F13: 0.6 | G13: 1.5 | H13: 0.8 | I13: -0.4 | J13: -1.2 | K13: -1.35 | L13: 1.35 | M13: 2 | N13: 2x I-260 ยาว 22 ม. | O13: =F13*G13*H13 | P13: =2*(F13+G13)*H13 | Q13: =IF(L13>0,(F13+2*0.1)*(G13+2*0.1)*L13,0) | R13: =(F13+0.2)*(G13+0.2)*0.1 | S13: =(F13+0.2)*(G13+0.2)*0.05 | T13: =INDEX('2-ฐานราก เหล็กเสริม'!$S:$S,MATCH(B13,'2-ฐานราก เหล็กเสริม'!$A:$A,0)) | U13: M22 | V13: แบบ S201 (ตำแหน่ง) / ระดับรอยืนยัน
A14: F2P-011 | B14: F2P | C14: 11/A | D14: 59.993 | E14: 0.008 | F14: 1.5 | G14: 0.6 | H14: 0.8 | I14: -0.4 | J14: -1.2 | K14: -1.35 | L14: 1.35 | M14: 2 | N14: 2x I-260 ยาว 22 ม. | O14: =F14*G14*H14 | P14: =2*(F14+G14)*H14 | Q14: =IF(L14>0,(F14+2*0.1)*(G14+2*0.1)*L14,0) | R14: =(F14+0.2)*(G14+0.2)*0.1 | S14: =(F14+0.2)*(G14+0.2)*0.05 | T14: =INDEX('2-ฐานราก เหล็กเสริม'!$S:$S,MATCH(B14,'2-ฐานราก เหล็กเสริม'!$A:$A,0)) | U14: M22 | V14: แบบ S201 (ตำแหน่ง) / ระดับรอยืนยัน
A15: F2P-012 | B15: F2P | C15: 1/B | D15: -0.009 | E15: 6.012 | F15: 1.5 | G15: 0.6 | H15: 0.8 | I15: -0.4 | J15: -1.2 | K15: -1.35 | L15: 1.35 | M15: 2 | N15: 2x I-260 ยาว 22 ม. | O15: =F15*G15*H15 | P15: =2*(F15+G15)*H15 | Q15: =IF(L15>0,(F15+2*0.1)*(G15+2*0.1)*L15,0) | R15: =(F15+0.2)*(G15+0.2)*0.1 | S15: =(F15+0.2)*(G15+0.2)*0.05 | T15: =INDEX('2-ฐานราก เหล็กเสริม'!$S:$S,MATCH(B15,'2-ฐานราก เหล็กเสริม'!$A:$A,0)) | U15: M22 | V15: แบบ S201 (ตำแหน่ง) / ระดับรอยืนยัน
... A669: TRP-001 | B669: TRP | C669: 11+4.90/A-7.16 | D669: 64.9 | E669: -7.165 | F669: 5 | G669: 3 | H669: 0.4 | I669: 0 | J669: -0.4 | K669: -0.55 | L669: 0.55 | M669: 6 | N669: 6x I-220 ยาว 22 ม. | O669: =F669*G669*H669 | P669: =2*(F669+G669)*H669 | Q669: =IF(L669>0,(F669+2*0.1)*(G669+2*0.1)*L669,0) | R669: =(F669+0.2)*(G669+0.2)*0.1 | S669: =(F669+0.2)*(G669+0.2)*0.05 | T669: =INDEX('2-ฐานราก เหล็กเสริม'!$S:$S,MATCH(B669,'2-ฐานราก เหล็กเสริม'!$A:$A,0)) | U669: M45 | V669: แบบ A104
A671: รวม | M671: =SUM(M4:M669) | O671: =SUM(O4:O669) | P671: =SUM(P4:P669) | Q671: =SUM(Q4:Q669) | R671: =SUM(R4:R669) | S671: =SUM(S4:S669) | T671: =SUM(T4:T669)
A672: หมายเหตุ: ระดับท้องฐานตามที่ใช้ในโมเดล (F2P -1.20 จากความยาวเสา C1 4.90 ม. ตาราง S4.1, F1P +0.10 ชิดท้องพื้น S1, F1A -0.45 ชิดท้องพื้น S2, F1P-1 -1.00, แท่นหม้อแปลง -0.40 ตาม A104) ยังรอยืนยันจากแบบขยายฐานราก; ดินขุดคิดจากระดับดินเดิม ±0.00 เผื่อข้าง 0.1 ม. ใต้ฐานมีคอนกรีตหยาบ 0.05 + ทราย 0.1 ม.

Sheet 2-ฐานราก เหล็กเสริม
A1: เหล็กเสริมฐานราก แยกตามชนิด (กรอกช่องสีเหลืองตามเอกสารออกแบบ ระบบคำนวณน้ำหนักทุกฐานอัตโนมัติ)
A2: งานก่อสร้างอาคารโกดังและงานบริเวณ บริษัท ตงเฉิน อีเล็คทริค เคเบิ้ล แอนด์ไวร์ จำกัด | WEC-TC-6901
A3: ชนิด | B3: รายละเอียด | C3: ด้านยาว (ม.) | D3: ด้านสั้น (ม.) | E3: หนา (ม.) | F3: ระยะหุ้ม (ม.) | G3: ตะแกรงล่าง แนวยาว: จำนวน | H3: Ø (มม.) | I3: ตะแกรงล่าง แนวสั้น: จำนวน | J3: Ø (มม.) | K3: ตะแกรงบน แนวยาว: จำนวน | L3: Ø (มม.) | M3: ตะแกรงบน แนวสั้น: จำนวน | N3: Ø (มม.) | O3: เหล็กรัดรอบข้าง: จำนวนชั้น | P3: Ø (มม.) | Q3: งอปลาย (เท่าของ Ø) | R3: จำนวนฐาน | S3: เหล็กเสริม/ฐาน (กก.) | T3: เหล็กเสริมรวม (กก.) | U3: สถานะ
A4: F2P | B4: ฐานราก F2P 0.60x1.50x0.80 (เข็ม 2 ต้น) รับเสา C1/C2 | C4: 1.5 | D4: 0.6 | E4: 0.8 | F4: 0.075 | Q4: 12 | R4: =COUNTIF('1-ฐานราก รายจุด'!$B:$B,A4) | S4: =G4*(C4-2*F4+2*Q4*H4/1000)*H4^2/162 + I4*(D4-2*F4+2*Q4*J4/1000)*J4^2/162 + K4*(C4-2*F4+2*Q4*L4/1000)*L4^2/162 + M4*(D4-2*F4+2*Q4*N4/1000)*N4^2/162 + O4*(2*(C4+D4)-8*F4+0.3)*P4^2/162 | T4: =R4*S4 | U4: รอเอกสารออกแบบเหล็กเสริม
A5: F1P | B5: Drop panel F1P 1.00x1.00x0.20 ใต้พื้น S1 (เข็ม I35 1 ต้น) | C5: 1 | D5: 1 | E5: 0.2 | F5: 0.05 | Q5: 12 | R5: =COUNTIF('1-ฐานราก รายจุด'!$B:$B,A5) | S5: =G5*(C5-2*F5+2*Q5*H5/1000)*H5^2/162 + I5*(D5-2*F5+2*Q5*J5/1000)*J5^2/162 + K5*(C5-2*F5+2*Q5*L5/1000)*L5^2/162 + M5*(D5-2*F5+2*Q5*N5/1000)*N5^2/162 + O5*(2*(C5+D5)-8*F5+0.3)*P5^2/162 | T5: =R5*S5 | U5: รอเอกสารออกแบบเหล็กเสริม
A6: F1P-1 | B6: ฐาน F1P-1 0.60x0.60x0.60 อาคารประกอบ (เข็ม 1 ต้น) | C6: 0.6 | D6: 0.6 | E6: 0.6 | F6: 0.075 | Q6: 12 | R6: =COUNTIF('1-ฐานราก รายจุด'!$B:$B,A6) | S6: =G6*(C6-2*F6+2*Q6*H6/1000)*H6^2/162 + I6*(D6-2*F6+2*Q6*J6/1000)*J6^2/162 + K6*(C6-2*F6+2*Q6*L6/1000)*L6^2/162 + M6*(D6-2*F6+2*Q6*N6/1000)*N6^2/162 + O6*(2*(C6+D6)-8*F6+0.3)*P6^2/162 | T6: =R6*S6 | U6: รอเอกสารออกแบบเหล็กเสริม
A7: F1A | B7: ฐาน F1A 0.60x0.60x0.30 ใต้พื้นถนน S2 (เข็ม I22 1 ต้น) | C7: 0.6 | D7: 0.6 | E7: 0.3 | F7: 0.05 | Q7: 12 | R7: =COUNTIF('1-ฐานราก รายจุด'!$B:$B,A7) | S7: =G7*(C7-2*F7+2*Q7*H7/1000)*H7^2/162 + I7*(D7-2*F7+2*Q7*J7/1000)*J7^2/162 + K7*(C7-2*F7+2*Q7*L7/1000)*L7^2/162 + M7*(D7-2*F7+2*Q7*N7/1000)*N7^2/162 + O7*(2*(C7+D7)-8*F7+0.3)*P7^2/162 | T7: =R7*S7 | U7: รอเอกสารออกแบบเหล็กเสริม
A8: SQ66 | B8: ฐาน 0.66x0.66 แนวเขตที่ดิน (หน้าที่รอยืนยัน) | C8: 0.66 | D8: 0.66 | E8: 0.3 | F8: 0.05 | Q8: 12 | R8: =COUNTIF('1-ฐานราก รายจุด'!$B:$B,A8) | S8: =G8*(C8-2*F8+2*Q8*H8/1000)*H8^2/162 + I8*(D8-2*F8+2*Q8*J8/1000)*J8^2/162 + K8*(C8-2*F8+2*Q8*L8/1000)*L8^2/162 + M8*(D8-2*F8+2*Q8*N8/1000)*N8^2/162 + O8*(2*(C8+D8)-8*F8+0.3)*P8^2/162 | T8: =R8*S8 | U8: รอเอกสารออกแบบเหล็กเสริม
A9: TRP | B9: แท่นหม้อแปลง 750 kVA (A104) ฐาน 5.00x3.00x0.40 + แท่น 3.50x1.75x0.15 | C9: 5 | D9: 3 | E9: 0.4 | F9: 0.075 | Q9: 12 | R9: =COUNTIF('1-ฐานราก รายจุด'!$B:$B,A9) | S9: =G9*(C9-2*F9+2*Q9*H9/1000)*H9^2/162 + I9*(D9-2*F9+2*Q9*J9/1000)*J9^2/162 + K9*(C9-2*F9+2*Q9*L9/1000)*L9^2/162 + M9*(D9-2*F9+2*Q9*N9/1000)*N9^2/162 + O9*(2*(C9+D9)-8*F9+0.3)*P9^2/162 | T9: =R9*S9 | U9: รอเอกสารออกแบบเหล็กเสริม
A10: รวม | T10: =SUM(T4:T9)
A12: ตัวอย่างการกรอก: F2P ตะแกรงล่างแนวยาว 6 เส้น Ø16 → ช่อง G=6, H=16; ตะแกรงล่างแนวสั้น 10 เส้น Ø12 → I=10, J=12 (ระบุจำนวนเส้นจริงตามแบบ ไม่ใช่ระยะห่าง)
A13: เหล็กยืนของเสาที่ฝังในฐานราก คิดในชีต 4 (เสา) ไม่ซ้ำในชีตนี้

Sheet 3-เสา รายต้น
A1: ตารางเสา คสล. รายต้น (โคนเสา = หลังฐานราก, หัวเสา = +4.50 / อาคารประกอบ +3.00)
A2: งานก่อสร้างอาคารโกดังและงานบริเวณ บริษัท ตงเฉิน อีเล็คทริค เคเบิ้ล แอนด์ไวร์ จำกัด | WEC-TC-6901
A3: รหัส | B3: ชนิด | C3: ตำแหน่งกริด | D3: พิกัด x | E3: พิกัด y | F3: หน้าตัด X (ม.) | G3: หน้าตัด Y (ม.) | H3: ระดับโคนเสา | I3: ระดับหัวเสา | J3: ความสูง (ม.) | K3: ฐานรากรองรับ | L3: คอนกรีต (ลบ.ม.) | M3: ไม้แบบ (ตร.ม.) | N3: เหล็กเสริม (กก.) | O3: สถานะ
A4: C1-001 | B4: C1 | C4: 1/A | D4: -0.016 | E4: 0.008 | F4: 0.5 | G4: 0.3 | H4: -0.4 | I4: 4.5 | J4: =I4-H4 | K4: F2P-001 | L4: =F4*G4*J4 | M4: =2*(F4+G4)*J4 | N4: =INDEX('4-เสา เหล็กเสริม'!$O:$O,MATCH(B4,'4-เสา เหล็กเสริม'!$A:$A,0)) | O4: แบบ S201 (ตำแหน่ง) / ระดับรอยืนยัน
A5: C1-002 | B5: C1 | C5: 2/A | D5: 5.988 | E5: 0.008 | F5: 0.3 | G5: 0.5 | H5: -0.4 | I5: 4.5 | J5: =I5-H5 | K5: F2P-002 | L5: =F5*G5*J5 | M5: =2*(F5+G5)*J5 | N5: =INDEX('4-เสา เหล็กเสริม'!$O:$O,MATCH(B5,'4-เสา เหล็กเสริม'!$A:$A,0)) | O5: แบบ S201 (ตำแหน่ง) / ระดับรอยืนยัน
A6: C1-003 | B6: C1 | C6: 3/A | D6: 11.986 | E6: 0.008 | F6: 0.3 | G6: 0.5 | H6: -0.4 | I6: 4.5 | J6: =I6-H6 | K6: F2P-003 | L6: =F6*G6*J6 | M6: =2*(F6+G6)*J6 | N6: =INDEX('4-เสา เหล็กเสริม'!$O:$O,MATCH(B6,'4-เสา เหล็กเสริม'!$A:$A,0)) | O6: แบบ S201 (ตำแหน่ง) / ระดับรอยืนยัน
A7: C1-004 | B7: C1 | C7: 4/A | D7: 17.99 | E7: 0.008 | F7: 0.3 | G7: 0.5 | H7: -0.4 | I7: 4.5 | J7: =I7-H7 | K7: F2P-004 | L7: =F7*G7*J7 | M7: =2*(F7+G7)*J7 | N7: =INDEX('4-เสา เหล็กเสริม'!$O:$O,MATCH(B7,'4-เสา เหล็กเสริม'!$A:$A,0)) | O7: แบบ S201 (ตำแหน่ง) / ระดับรอยืนยัน
A8: C1-005 | B8: C1 | C8: 5/A | D8: 23.994 | E8: 0.008 | F8: 0.3 | G8: 0.5 | H8: -0.4 | I8: 4.5 | J8: =I8-H8 | K8: F2P-005 | L8: =F8*G8*J8 | M8: =2*(F8+G8)*J8 | N8: =INDEX('4-เสา เหล็กเสริม'!$O:$O,MATCH(B8,'4-เสา เหล็กเสริม'!$A:$A,0)) | O8: แบบ S201 (ตำแหน่ง) / ระดับรอยืนยัน
A9: C1-006 | B9: C1 | C9: 6/A | D9: 29.992 | E9: 0.008 | F9: 0.3 | G9: 0.5 | H9: -0.4 | I9: 4.5 | J9: =I9-H9 | K9: F2P-006 | L9: =F9*G9*J9 | M9: =2*(F9+G9)*J9 | N9: =INDEX('4-เสา เหล็กเสริม'!$O:$O,MATCH(B9,'4-เสา เหล็กเสริม'!$A:$A,0)) | O9: แบบ S201 (ตำแหน่ง) / ระดับรอยืนยัน
A10: C1-007 | B10: C1 | C10: 7/A | D10: 35.989 | E10: 0.008 | F10: 0.3 | G10: 0.5 | H10: -0.4 | I10: 4.5 | J10: =I10-H10 | K10: F2P-007 | L10: =F10*G10*J10 | M10: =2*(F10+G10)*J10 | N10: =INDEX('4-เสา เหล็กเสริม'!$O:$O,MATCH(B10,'4-เสา เหล็กเสริม'!$A:$A,0)) | O10: แบบ S201 (ตำแหน่ง) / ระดับรอยืนยัน
A11: C1-008 | B11: C1 | C11: 8/A | D11: 41.994 | E11: 0.008 | F11: 0.3 | G11: 0.5 | H11: -0.4 | I11: 4.5 | J11: =I11-H11 | K11: F2P-008 | L11: =F11*G11*J11 | M11: =2*(F11+G11)*J11 | N11: =INDEX('4-เสา เหล็กเสริม'!$O:$O,MATCH(B11,'4-เสา เหล็กเสริม'!$A:$A,0)) | O11: แบบ S201 (ตำแหน่ง) / ระดับรอยืนยัน
A12: C1-009 | B12: C1 | C12: 9/A | D12: 47.991 | E12: 0.008 | F12: 0.3 | G12: 0.5 | H12: -0.4 | I12: 4.5 | J12: =I12-H12 | K12: F2P-009 | L12: =F12*G12*J12 | M12: =2*(F12+G12)*J12 | N12: =INDEX('4-เสา เหล็กเสริม'!$O:$O,MATCH(B12,'4-เสา เหล็กเสริม'!$A:$A,0)) | O12: แบบ S201 (ตำแหน่ง) / ระดับรอยืนยัน
A13: C1-010 | B13: C1 | C13: 10/A | D13: 53.995 | E13: 0.008 | F13: 0.3 | G13: 0.5 | H13: -0.4 | I13: 4.5 | J13: =I13-H13 | K13: F2P-010 | L13: =F13*G13*J13 | M13: =2*(F13+G13)*J13 | N13: =INDEX('4-เสา เหล็กเสริม'!$O:$O,MATCH(B13,'4-เสา เหล็กเสริม'!$A:$A,0)) | O13: แบบ S201 (ตำแหน่ง) / ระดับรอยืนยัน
A14: C1-011 | B14: C1 | C14: 11/A | D14: 59.993 | E14: 0.008 | F14: 0.5 | G14: 0.3 | H14: -0.4 | I14: 4.5 | J14: =I14-H14 | K14: F2P-011 | L14: =F14*G14*J14 | M14: =2*(F14+G14)*J14 | N14: =INDEX('4-เสา เหล็กเสริม'!$O:$O,MATCH(B14,'4-เสา เหล็กเสริม'!$A:$A,0)) | O14: แบบ S201 (ตำแหน่ง) / ระดับรอยืนยัน
A15: C1-012 | B15: C1 | C15: 1/B | D15: -0.016 | E15: 6.012 | F15: 0.5 | G15: 0.3 | H15: -0.4 | I15: 4.5 | J15: =I15-H15 | K15: F2P-012 | L15: =F15*G15*J15 | M15: =2*(F15+G15)*J15 | N15: =INDEX('4-เสา เหล็กเสริม'!$O:$O,MATCH(B15,'4-เสา เหล็กเสริม'!$A:$A,0)) | O15: แบบ S201 (ตำแหน่ง) / ระดับรอยืนยัน
... A56: C3-007 | B56: C3 | C56: 1-4.96/E+2.01 | D56: -4.961 | E56: 26.011 | F56: 0.2 | G56: 0.2 | H56: -0.4 | I56: 3 | J56: =I56-H56 | K56: F1P-1-011 | L56: =F56*G56*J56 | M56: =2*(F56+G56)*J56 | N56: =INDEX('4-เสา เหล็กเสริม'!$O:$O,MATCH(B56,'4-เสา เหล็กเสริม'!$A:$A,0)) | O56: แบบ S201 (ตำแหน่ง) / ระดับรอยืนยัน
A57: SC-001 | B57: SC | C57: 1+3.00/A | D57: 3 | E57: 0 | F57: 0.1 | G57: 0.15 | H57: 0.5 | I57: 4.35 | J57: =I57-H57 | K57: ผนัง/คานคอดิน | L57: =F57*G57*J57 | M57: =2*MIN(F57,G57)*J57 | N57: =INDEX('4-เสา เหล็กเสริม'!$O:$O,MATCH(B57,'4-เสา เหล็กเสริม'!$A:$A,0)) | O57: สมมติ: กลางช่วงเสา 6 ม. และข้างวงกบ
A58: SC-002 | B58: SC | C58: 2+3.00/A | D58: 9 | E58: 0 | F58: 0.1 | G58: 0.15 | H58: 0.5 | I58: 4.35 | J58: =I58-H58 | K58: ผนัง/คานคอดิน | L58: =F58*G58*J58 | M58: =2*MIN(F58,G58)*J58 | N58: =INDEX('4-เสา เหล็กเสริม'!$O:$O,MATCH(B58,'4-เสา เหล็กเสริม'!$A:$A,0)) | O58: สมมติ: กลางช่วงเสา 6 ม. และข้างวงกบ
A59: SC-003 | B59: SC | C59: 3+3.00/A | D59: 15 | E59: 0 | F59: 0.1 | G59: 0.15 | H59: 0.5 | I59: 4.35 | J59: =I59-H59 | K59: ผนัง/คานคอดิน | L59: =F59*G59*J59 | M59: =2*MIN(F59,G59)*J59 | N59: =INDEX('4-เสา เหล็กเสริม'!$O:$O,MATCH(B59,'4-เสา เหล็กเสริม'!$A:$A,0)) | O59: สมมติ: กลางช่วงเสา 6 ม. และข้างวงกบ
A60: SC-004 | B60: SC | C60: 4+3.00/A | D60: 21 | E60: 0 | F60: 0.1 | G60: 0.15 | H60: 0.5 | I60: 4.35 | J60: =I60-H60 | K60: ผนัง/คานคอดิน | L60: =F60*G60*J60 | M60: =2*MIN(F60,G60)*J60 | N60: =INDEX('4-เสา เหล็กเสริม'!$O:$O,MATCH(B60,'4-เสา เหล็กเสริม'!$A:$A,0)) | O60: สมมติ: กลางช่วงเสา 6 ม. และข้างวงกบ
A61: SC-005 | B61: SC | C61: 6+3.00/A | D61: 33 | E61: 0 | F61: 0.1 | G61: 0.15 | H61: 0.5 | I61: 4.35 | J61: =I61-H61 | K61: ผนัง/คานคอดิน | L61: =F61*G61*J61 | M61: =2*MIN(F61,G61)*J61 | N61: =INDEX('4-เสา เหล็กเสริม'!$O:$O,MATCH(B61,'4-เสา เหล็กเสริม'!$A:$A,0)) | O61: สมมติ: กลางช่วงเสา 6 ม. และข้างวงกบ
A62: SC-006 | B62: SC | C62: 7+3.00/A | D62: 39 | E62: 0 | F62: 0.1 | G62: 0.15 | H62: 0.5 | I62: 4.35 | J62: =I62-H62 | K62: ผนัง/คานคอดิน | L62: =F62*G62*J62 | M62: =2*MIN(F62,G62)*J62 | N62: =INDEX('4-เสา เหล็กเสริม'!$O:$O,MATCH(B62,'4-เสา เหล็กเสริม'!$A:$A,0)) | O62: สมมติ: กลางช่วงเสา 6 ม. และข้างวงกบ
A63: SC-007 | B63: SC | C63: 8+3.00/A | D63: 45 | E63: 0 | F63: 0.1 | G63: 0.15 | H63: 0.5 | I63: 4.35 | J63: =I63-H63 | K63: ผนัง/คานคอดิน | L63: =F63*G63*J63 | M63: =2*MIN(F63,G63)*J63 | N63: =INDEX('4-เสา เหล็กเสริม'!$O:$O,MATCH(B63,'4-เสา เหล็กเสริม'!$A:$A,0)) | O63: สมมติ: กลางช่วงเสา 6 ม. และข้างวงกบ
A64: SC-008 | B64: SC | C64: 9+3.00/A | D64: 51 | E64: 0 | F64: 0.1 | G64: 0.15 | H64: 0.5 | I64: 4.35 | J64: =I64-H64 | K64: ผนัง/คานคอดิน | L64: =F64*G64*J64 | M64: =2*MIN(F64,G64)*J64 | N64: =INDEX('4-เสา เหล็กเสริม'!$O:$O,MATCH(B64,'4-เสา เหล็กเสริม'!$A:$A,0)) | O64: สมมติ: กลางช่วงเสา 6 ม. และข้างวงกบ
A65: SC-009 | B65: SC | C65: 10+3.00/A | D65: 57 | E65: 0 | F65: 0.1 | G65: 0.15 | H65: 0.5 | I65: 4.35 | J65: =I65-H65 | K65: ผนัง/คานคอดิน | L65: =F65*G65*J65 | M65: =2*MIN(F65,G65)*J65 | N65: =INDEX('4-เสา เหล็กเสริม'!$O:$O,MATCH(B65,'4-เสา เหล็กเสริม'!$A:$A,0)) | O65: สมมติ: กลางช่วงเสา 6 ม. และข้างวงกบ
A66: SC-010 | B66: SC | C66: 1/A+3.00 | D66: 0 | E66: 3 | F66: 0.15 | G66: 0.1 | H66: 0.5 | I66: 4.35 | J66: =I66-H66 | K66: ผนัง/คานคอดิน | L66: =F66*G66*J66 | M66: =2*MIN(F66,G66)*J66 | N66: =INDEX('4-เสา เหล็กเสริม'!$O:$O,MATCH(B66,'4-เสา เหล็กเสริม'!$A:$A,0)) | O66: สมมติ: กลางช่วงเสา 6 ม. และข้างวงกบ
A67: SC-011 | B67: SC | C67: 11/A+3.00 | D67: 60 | E67: 3 | F67: 0.15 | G67: 0.1 | H67: 0.5 | I67: 4.35 | J67: =I67-H67 | K67: ผนัง/คานคอดิน | L67: =F67*G67*J67 | M67: =2*MIN(F67,G67)*J67 | N67: =INDEX('4-เสา เหล็กเสริม'!$O:$O,MATCH(B67,'4-เสา เหล็กเสริม'!$A:$A,0)) | O67: สมมติ: กลางช่วงเสา 6 ม. และข้างวงกบ
A68: SC-012 | B68: SC | C68: 1/B+3.00 | D68: 0 | E68: 9 | F68: 0.15 | G68: 0.1 | H68: 0.5 | I68: 4.35 | J68: =I68-H68 | K68: ผนัง/คานคอดิน | L68: =F68*G68*J68 | M68: =2*MIN(F68,G68)*J68 | N68: =INDEX('4-เสา เหล็กเสริม'!$O:$O,MATCH(B68,'4-เสา เหล็กเสริม'!$A:$A,0)) | O68: สมมติ: กลางช่วงเสา 6 ม. และข้างวงกบ
... A94: SC-038 | B94: SC | C94: 10+3.00/J | D94: 57 | E94: 54 | F94: 0.1 | G94: 0.15 | H94: 0.5 | I94: 4.35 | J94: =I94-H94 | K94: ผนัง/คานคอดิน | L94: =F94*G94*J94 | M94: =2*MIN(F94,G94)*J94 | N94: =INDEX('4-เสา เหล็กเสริม'!$O:$O,MATCH(B94,'4-เสา เหล็กเสริม'!$A:$A,0)) | O94: สมมติ: กลางช่วงเสา 6 ม. และข้างวงกบ
A95: รวม | L95: =SUM(L4:L94) | M95: =SUM(M4:M94) | N95: =SUM(N4:N94)

Sheet 4-เสา เหล็กเสริม
A1: เหล็กเสริมเสา แยกตามชนิด (กรอกช่องสีเหลือง)
A2: งานก่อสร้างอาคารโกดังและงานบริเวณ บริษัท ตงเฉิน อีเล็คทริค เคเบิ้ล แอนด์ไวร์ จำกัด | WEC-TC-6901
A3: ชนิด | B3: รายละเอียด | C3: หน้าตัด b (ม.) | D3: หน้าตัด h (ม.) | E3: ระยะหุ้ม (ม.) | F3: เหล็กยืน: จำนวน | G3: Ø (มม.) | H3: ระยะทาบ/ฝัง (เท่าของ Ø) | I3: งอฝังในฐาน (ม.) | J3: ปลอก Ø (มม.) | K3: ระยะปลอก ช่วงปลาย (ม.) | L3: ระยะปลอก ช่วงกลาง (ม.) | M3: ความสูงเฉลี่ย (ม.) | N3: จำนวนต้น | O3: เหล็กเสริม/ต้น (กก.) | P3: เหล็กเสริมรวม (กก.) | Q3: สถานะ
A4: C1 | B4: เสา C1 0.30x0.50 จากหลังฐาน F2P ถึง +4.50 | C4: 0.3 | D4: 0.5 | E4: 0.04 | H4: 40 | I4: 0.3 | M4: =AVERAGEIF('3-เสา รายต้น'!$B:$B,A4,'3-เสา รายต้น'!$J:$J) | N4: =COUNTIF('3-เสา รายต้น'!$B:$B,A4) | O4: =F4*(M4+H4*G4/1000+I4)*G4^2/162 + IF(J4=0,0,(2*ROUNDUP(M4/4/K4,0)+ROUNDUP(M4/2/L4,0)+1)*(2*(C4+D4)-8*E4+24*J4/1000)*J4^2/162) | P4: =N4*O4 | Q4: รอเอกสารออกแบบเหล็กเสริม
A5: C2 | B5: เสา C2 0.50x0.50 (6/J) | C5: 0.5 | D5: 0.5 | E5: 0.04 | H5: 40 | I5: 0.3 | M5: =AVERAGEIF('3-เสา รายต้น'!$B:$B,A5,'3-เสา รายต้น'!$J:$J) | N5: =COUNTIF('3-เสา รายต้น'!$B:$B,A5) | O5: =F5*(M5+H5*G5/1000+I5)*G5^2/162 + IF(J5=0,0,(2*ROUNDUP(M5/4/K5,0)+ROUNDUP(M5/2/L5,0)+1)*(2*(C5+D5)-8*E5+24*J5/1000)*J5^2/162) | P5: =N5*O5 | Q5: รอเอกสารออกแบบเหล็กเสริม
A6: C3 | B6: เสา C3 0.20x0.20 อาคารประกอบ | C6: 0.2 | D6: 0.2 | E6: 0.04 | H6: 40 | I6: 0.3 | M6: =AVERAGEIF('3-เสา รายต้น'!$B:$B,A6,'3-เสา รายต้น'!$J:$J) | N6: =COUNTIF('3-เสา รายต้น'!$B:$B,A6) | O6: =F6*(M6+H6*G6/1000+I6)*G6^2/162 + IF(J6=0,0,(2*ROUNDUP(M6/4/K6,0)+ROUNDUP(M6/2/L6,0)+1)*(2*(C6+D6)-8*E6+24*J6/1000)*J6^2/162) | P6: =N6*O6 | Q6: รอเอกสารออกแบบเหล็กเสริม
A7: SC | B7: เสาเอ็น 0.15x0.10 ในผนังก่อ +0.50 ถึง +4.35 | C7: 0.1 | D7: 0.15 | E7: 0.02 | H7: 40 | I7: 0 | M7: =AVERAGEIF('3-เสา รายต้น'!$B:$B,A7,'3-เสา รายต้น'!$J:$J) | N7: =COUNTIF('3-เสา รายต้น'!$B:$B,A7) | O7: =F7*(M7+H7*G7/1000+I7)*G7^2/162 + IF(J7=0,0,(2*ROUNDUP(M7/4/K7,0)+ROUNDUP(M7/2/L7,0)+1)*(2*(C7+D7)-8*E7+24*J7/1000)*J7^2/162) | P7: =N7*O7 | Q7: รอเอกสารออกแบบเหล็กเสริม
A8: รวม | P8: =SUM(P4:P7)
A10: หมายเหตุ: ถ้าไม่กรอกระยะปลอก ระบบไม่คิดปลอก (ป้องกันหารด้วยศูนย์) ช่วงปลาย = 1/4 ของความสูงแต่ละด้าน

Sheet 5-คาน รายช่วง
A1: ตารางคาน คสล. รายช่วง: หน้าตัด ความยาว ระดับ ปริมาณ และเหล็กเสริม (สูตรอ้างชีต 6)
A2: งานก่อสร้างอาคารโกดังและงานบริเวณ บริษัท ตงเฉิน อีเล็คทริค เคเบิ้ล แอนด์ไวร์ จำกัด | WEC-TC-6901
A3: รหัส | B3: ชนิด | C3: แนว | D3: จาก (กริด) | E3: ถึง (กริด) | F3: ยาว ศก.-ศก. (ม.) | G3: ยาวสุทธิ ผิว-ผิว (ม.) | H3: กว้าง b (ม.) | I3: ลึก h (ม.) | J3: ระดับหลังคาน | K3: ระดับท้องคาน | L3: คอนกรีต (ลบ.ม.) | M3: ไม้แบบ (ตร.ม.) | N3: เหล็กบน (กก.) | O3: เหล็กล่าง (กก.) | P3: เหล็กเสริมพิเศษ (กก.) | Q3: ปลอก (กก.) | R3: ปลอก (ตัว) | S3: เหล็กรวม (กก.) | T3: สถานะ
A4: B1-001 | B4: B1 | C4: แนว A | D4: 1/A | E4: 2/A | F4: 6 | G4: 5.7 | H4: 0.2 | I4: 0.6 | J4: 0.5 | K4: -0.1 | L4: =H4*I4*G4 | M4: =(2*I4+H4)*G4 | N4: =INDEX('6-คาน เหล็กเสริม'!$E:$E,MATCH($B4,'6-คาน เหล็กเสริม'!$A:$A,0))*(F4+2*INDEX('6-คาน เหล็กเสริม'!$Q:$Q,MATCH($B4,'6-คาน เหล็กเสริม'!$A:$A,0))*INDEX('6-คาน เหล็กเสริม'!$F:$F,MATCH($B4,'6-คาน เหล็กเสริม'!$A:$A,0))/1000)*INDEX('6-คาน เหล็กเสริม'!$F:$F,MATCH($B4,'6-คาน เหล็กเสริม'!$A:$A,0))^2/162 | O4: =INDEX('6-คาน เหล็กเสริม'!$G:$G,MATCH($B4,'6-คาน เหล็กเสริม'!$A:$A,0))*(F4+2*INDEX('6-คาน เหล็กเสริม'!$Q:$Q,MATCH($B4,'6-คาน เหล็กเสริม'!$A:$A,0))*INDEX('6-คาน เหล็กเสริม'!$H:$H,MATCH($B4,'6-คาน เหล็กเสริม'!$A:$A,0))/1000)*INDEX('6-คาน เหล็กเสริม'!$H:$H,MATCH($B4,'6-คาน เหล็กเสริม'!$A:$A,0))^2/162 | P4: =INDEX('6-คาน เหล็กเสริม'!$I:$I,MATCH($B4,'6-คาน เหล็กเสริม'!$A:$A,0))*2*(0.3*G4+INDEX('6-คาน เหล็กเสริม'!$Q:$Q,MATCH($B4,'6-คาน เหล็กเสริม'!$A:$A,0))*INDEX('6-คาน เหล็กเสริม'!$J:$J,MATCH($B4,'6-คาน เหล็กเสริม'!$A:$A,0))/1000)*INDEX('6-คาน เหล็กเสริม'!$J:$J,MATCH($B4,'6-คาน เหล็กเสริม'!$A:$A,0))^2/162+INDEX('6-คาน เหล็กเสริม'!$K:$K,MATCH($B4,'6-คาน เหล็กเสริม'!$A:$A,0))*0.7*G4*INDEX('6-คาน เหล็กเสริม'!$L:$L,MATCH($B4,'6-คาน เหล็กเสริม'!$A:$A,0))^2/162 | Q4: =R4*(2*(H4+I4)-8*INDEX('6-คาน เหล็กเสริม'!$P:$P,MATCH($B4,'6-คาน เหล็กเสริม'!$A:$A,0))+24*INDEX('6-คาน เหล็กเสริม'!$M:$M,MATCH($B4,'6-คาน เหล็กเสริม'!$A:$A,0))/1000)*INDEX('6-คาน เหล็กเสริม'!$M:$M,MATCH($B4,'6-คาน เหล็กเสริม'!$A:$A,0))^2/162 | R4: =IF(INDEX('6-คาน เหล็กเสริม'!$M:$M,MATCH($B4,'6-คาน เหล็กเสริม'!$A:$A,0))=0,0,2*ROUNDUP(G4/4/INDEX('6-คาน เหล็กเสริม'!$N:$N,MATCH($B4,'6-คาน เหล็กเสริม'!$A:$A,0)),0)+ROUNDUP(G4/2/INDEX('6-คาน เหล็กเสริม'!$O:$O,MATCH($B4,'6-คาน เหล็กเสริม'!$A:$A,0)),0)+1) | S4: =SUM(N4:Q4) | T4: แบบ
A5: B1-002 | B5: B1 | C5: แนว A | D5: 2/A | E5: 3/A | F5: 6 | G5: 5.7 | H5: 0.2 | I5: 0.6 | J5: 0.5 | K5: -0.1 | L5: =H5*I5*G5 | M5: =(2*I5+H5)*G5 | N5: =INDEX('6-คาน เหล็กเสริม'!$E:$E,MATCH($B5,'6-คาน เหล็กเสริม'!$A:$A,0))*(F5+2*INDEX('6-คาน เหล็กเสริม'!$Q:$Q,MATCH($B5,'6-คาน เหล็กเสริม'!$A:$A,0))*INDEX('6-คาน เหล็กเสริม'!$F:$F,MATCH($B5,'6-คาน เหล็กเสริม'!$A:$A,0))/1000)*INDEX('6-คาน เหล็กเสริม'!$F:$F,MATCH($B5,'6-คาน เหล็กเสริม'!$A:$A,0))^2/162 | O5: =INDEX('6-คาน เหล็กเสริม'!$G:$G,MATCH($B5,'6-คาน เหล็กเสริม'!$A:$A,0))*(F5+2*INDEX('6-คาน เหล็กเสริม'!$Q:$Q,MATCH($B5,'6-คาน เหล็กเสริม'!$A:$A,0))*INDEX('6-คาน เหล็กเสริม'!$H:$H,MATCH($B5,'6-คาน เหล็กเสริม'!$A:$A,0))/1000)*INDEX('6-คาน เหล็กเสริม'!$H:$H,MATCH($B5,'6-คาน เหล็กเสริม'!$A:$A,0))^2/162 | P5: =INDEX('6-คาน เหล็กเสริม'!$I:$I,MATCH($B5,'6-คาน เหล็กเสริม'!$A:$A,0))*2*(0.3*G5+INDEX('6-คาน เหล็กเสริม'!$Q:$Q,MATCH($B5,'6-คาน เหล็กเสริม'!$A:$A,0))*INDEX('6-คาน เหล็กเสริม'!$J:$J,MATCH($B5,'6-คาน เหล็กเสริม'!$A:$A,0))/1000)*INDEX('6-คาน เหล็กเสริม'!$J:$J,MATCH($B5,'6-คาน เหล็กเสริม'!$A:$A,0))^2/162+INDEX('6-คาน เหล็กเสริม'!$K:$K,MATCH($B5,'6-คาน เหล็กเสริม'!$A:$A,0))*0.7*G5*INDEX('6-คาน เหล็กเสริม'!$L:$L,MATCH($B5,'6-คาน เหล็กเสริม'!$A:$A,0))^2/162 | Q5: =R5*(2*(H5+I5)-8*INDEX('6-คาน เหล็กเสริม'!$P:$P,MATCH($B5,'6-คาน เหล็กเสริม'!$A:$A,0))+24*INDEX('6-คาน เหล็กเสริม'!$M:$M,MATCH($B5,'6-คาน เหล็กเสริม'!$A:$A,0))/1000)*INDEX('6-คาน เหล็กเสริม'!$M:$M,MATCH($B5,'6-คาน เหล็กเสริม'!$A:$A,0))^2/162 | R5: =IF(INDEX('6-คาน เหล็กเสริม'!$M:$M,MATCH($B5,'6-คาน เหล็กเสริม'!$A:$A,0))=0,0,2*ROUNDUP(G5/4/INDEX('6-คาน เหล็กเสริม'!$N:$N,MATCH($B5,'6-คาน เหล็กเสริม'!$A:$A,0)),0)+ROUNDUP(G5/2/INDEX('6-คาน เหล็กเสริม'!$O:$O,MATCH($B5,'6-คาน เหล็กเสริม'!$A:$A,0)),0)+1) | S5: =SUM(N5:Q5) | T5: แบบ
A6: B1-003 | B6: B1 | C6: แนว A | D6: 3/A | E6: 4/A | F6: 6 | G6: 5.7 | H6: 0.2 | I6: 0.6 | J6: 0.5 | K6: -0.1 | L6: =H6*I6*G6 | M6: =(2*I6+H6)*G6 | N6: =INDEX('6-คาน เหล็กเสริม'!$E:$E,MATCH($B6,'6-คาน เหล็กเสริม'!$A:$A,0))*(F6+2*INDEX('6-คาน เหล็กเสริม'!$Q:$Q,MATCH($B6,'6-คาน เหล็กเสริม'!$A:$A,0))*INDEX('6-คาน เหล็กเสริม'!$F:$F,MATCH($B6,'6-คาน เหล็กเสริม'!$A:$A,0))/1000)*INDEX('6-คาน เหล็กเสริม'!$F:$F,MATCH($B6,'6-คาน เหล็กเสริม'!$A:$A,0))^2/162 | O6: =INDEX('6-คาน เหล็กเสริม'!$G:$G,MATCH($B6,'6-คาน เหล็กเสริม'!$A:$A,0))*(F6+2*INDEX('6-คาน เหล็กเสริม'!$Q:$Q,MATCH($B6,'6-คาน เหล็กเสริม'!$A:$A,0))*INDEX('6-คาน เหล็กเสริม'!$H:$H,MATCH($B6,'6-คาน เหล็กเสริม'!$A:$A,0))/1000)*INDEX('6-คาน เหล็กเสริม'!$H:$H,MATCH($B6,'6-คาน เหล็กเสริม'!$A:$A,0))^2/162 | P6: =INDEX('6-คาน เหล็กเสริม'!$I:$I,MATCH($B6,'6-คาน เหล็กเสริม'!$A:$A,0))*2*(0.3*G6+INDEX('6-คาน เหล็กเสริม'!$Q:$Q,MATCH($B6,'6-คาน เหล็กเสริม'!$A:$A,0))*INDEX('6-คาน เหล็กเสริม'!$J:$J,MATCH($B6,'6-คาน เหล็กเสริม'!$A:$A,0))/1000)*INDEX('6-คาน เหล็กเสริม'!$J:$J,MATCH($B6,'6-คาน เหล็กเสริม'!$A:$A,0))^2/162+INDEX('6-คาน เหล็กเสริม'!$K:$K,MATCH($B6,'6-คาน เหล็กเสริม'!$A:$A,0))*0.7*G6*INDEX('6-คาน เหล็กเสริม'!$L:$L,MATCH($B6,'6-คาน เหล็กเสริม'!$A:$A,0))^2/162 | Q6: =R6*(2*(H6+I6)-8*INDEX('6-คาน เหล็กเสริม'!$P:$P,MATCH($B6,'6-คาน เหล็กเสริม'!$A:$A,0))+24*INDEX('6-คาน เหล็กเสริม'!$M:$M,MATCH($B6,'6-คาน เหล็กเสริม'!$A:$A,0))/1000)*INDEX('6-คาน เหล็กเสริม'!$M:$M,MATCH($B6,'6-คาน เหล็กเสริม'!$A:$A,0))^2/162 | R6: =IF(INDEX('6-คาน เหล็กเสริม'!$M:$M,MATCH($B6,'6-คาน เหล็กเสริม'!$A:$A,0))=0,0,2*ROUNDUP(G6/4/INDEX('6-คาน เหล็กเสริม'!$N:$N,MATCH($B6,'6-คาน เหล็กเสริม'!$A:$A,0)),0)+ROUNDUP(G6/2/INDEX('6-คาน เหล็กเสริม'!$O:$O,MATCH($B6,'6-คาน เหล็กเสริม'!$A:$A,0)),0)+1) | S6: =SUM(N6:Q6) | T6: แบบ
A7: B1-004 | B7: B1 | C7: แนว A | D7: 4/A | E7: 5/A | F7: 6 | G7: 5.7 | H7: 0.2 | I7: 0.6 | J7: 0.5 | K7: -0.1 | L7: =H7*I7*G7 | M7: =(2*I7+H7)*G7 | N7: =INDEX('6-คาน เหล็กเสริม'!$E:$E,MATCH($B7,'6-คาน เหล็กเสริม'!$A:$A,0))*(F7+2*INDEX('6-คาน เหล็กเสริม'!$Q:$Q,MATCH($B7,'6-คาน เหล็กเสริม'!$A:$A,0))*INDEX('6-คาน เหล็กเสริม'!$F:$F,MATCH($B7,'6-คาน เหล็กเสริม'!$A:$A,0))/1000)*INDEX('6-คาน เหล็กเสริม'!$F:$F,MATCH($B7,'6-คาน เหล็กเสริม'!$A:$A,0))^2/162 | O7: =INDEX('6-คาน เหล็กเสริม'!$G:$G,MATCH($B7,'6-คาน เหล็กเสริม'!$A:$A,0))*(F7+2*INDEX('6-คาน เหล็กเสริม'!$Q:$Q,MATCH($B7,'6-คาน เหล็กเสริม'!$A:$A,0))*INDEX('6-คาน เหล็กเสริม'!$H:$H,MATCH($B7,'6-คาน เหล็กเสริม'!$A:$A,0))/1000)*INDEX('6-คาน เหล็กเสริม'!$H:$H,MATCH($B7,'6-คาน เหล็กเสริม'!$A:$A,0))^2/162 | P7: =INDEX('6-คาน เหล็กเสริม'!$I:$I,MATCH($B7,'6-คาน เหล็กเสริม'!$A:$A,0))*2*(0.3*G7+INDEX('6-คาน เหล็กเสริม'!$Q:$Q,MATCH($B7,'6-คาน เหล็กเสริม'!$A:$A,0))*INDEX('6-คาน เหล็กเสริม'!$J:$J,MATCH($B7,'6-คาน เหล็กเสริม'!$A:$A,0))/1000)*INDEX('6-คาน เหล็กเสริม'!$J:$J,MATCH($B7,'6-คาน เหล็กเสริม'!$A:$A,0))^2/162+INDEX('6-คาน เหล็กเสริม'!$K:$K,MATCH($B7,'6-คาน เหล็กเสริม'!$A:$A,0))*0.7*G7*INDEX('6-คาน เหล็กเสริม'!$L:$L,MATCH($B7,'6-คาน เหล็กเสริม'!$A:$A,0))^2/162 | Q7: =R7*(2*(H7+I7)-8*INDEX('6-คาน เหล็กเสริม'!$P:$P,MATCH($B7,'6-คาน เหล็กเสริม'!$A:$A,0))+24*INDEX('6-คาน เหล็กเสริม'!$M:$M,MATCH($B7,'6-คาน เหล็กเสริม'!$A:$A,0))/1000)*INDEX('6-คาน เหล็กเสริม'!$M:$M,MATCH($B7,'6-คาน เหล็กเสริม'!$A:$A,0))^2/162 | R7: =IF(INDEX('6-คาน เหล็กเสริม'!$M:$M,MATCH($B7,'6-คาน เหล็กเสริม'!$A:$A,0))=0,0,2*ROUNDUP(G7/4/INDEX('6-คาน เหล็กเสริม'!$N:$N,MATCH($B7,'6-คาน เหล็กเสริม'!$A:$A,0)),0)+ROUNDUP(G7/2/INDEX('6-คาน เหล็กเสริม'!$O:$O,MATCH($B7,'6-คาน เหล็กเสริม'!$A:$A,0)),0)+1) | S7: =SUM(N7:Q7) | T7: แบบ
A8: B1-005 | B8: B1 | C8: แนว A | D8: 5/A | E8: 6/A | F8: 6 | G8: 5.7 | H8: 0.2 | I8: 0.6 | J8: 0.5 | K8: -0.1 | L8: =H8*I8*G8 | M8: =(2*I8+H8)*G8 | N8: =INDEX('6-คาน เหล็กเสริม'!$E:$E,MATCH($B8,'6-คาน เหล็กเสริม'!$A:$A,0))*(F8+2*INDEX('6-คาน เหล็กเสริม'!$Q:$Q,MATCH($B8,'6-คาน เหล็กเสริม'!$A:$A,0))*INDEX('6-คาน เหล็กเสริม'!$F:$F,MATCH($B8,'6-คาน เหล็กเสริม'!$A:$A,0))/1000)*INDEX('6-คาน เหล็กเสริม'!$F:$F,MATCH($B8,'6-คาน เหล็กเสริม'!$A:$A,0))^2/162 | O8: =INDEX('6-คาน เหล็กเสริม'!$G:$G,MATCH($B8,'6-คาน เหล็กเสริม'!$A:$A,0))*(F8+2*INDEX('6-คาน เหล็กเสริม'!$Q:$Q,MATCH($B8,'6-คาน เหล็กเสริม'!$A:$A,0))*INDEX('6-คาน เหล็กเสริม'!$H:$H,MATCH($B8,'6-คาน เหล็กเสริม'!$A:$A,0))/1000)*INDEX('6-คาน เหล็กเสริม'!$H:$H,MATCH($B8,'6-คาน เหล็กเสริม'!$A:$A,0))^2/162 | P8: =INDEX('6-คาน เหล็กเสริม'!$I:$I,MATCH($B8,'6-คาน เหล็กเสริม'!$A:$A,0))*2*(0.3*G8+INDEX('6-คาน เหล็กเสริม'!$Q:$Q,MATCH($B8,'6-คาน เหล็กเสริม'!$A:$A,0))*INDEX('6-คาน เหล็กเสริม'!$J:$J,MATCH($B8,'6-คาน เหล็กเสริม'!$A:$A,0))/1000)*INDEX('6-คาน เหล็กเสริม'!$J:$J,MATCH($B8,'6-คาน เหล็กเสริม'!$A:$A,0))^2/162+INDEX('6-คาน เหล็กเสริม'!$K:$K,MATCH($B8,'6-คาน เหล็กเสริม'!$A:$A,0))*0.7*G8*INDEX('6-คาน เหล็กเสริม'!$L:$L,MATCH($B8,'6-คาน เหล็กเสริม'!$A:$A,0))^2/162 | Q8: =R8*(2*(H8+I8)-8*INDEX('6-คาน เหล็กเสริม'!$P:$P,MATCH($B8,'6-คาน เหล็กเสริม'!$A:$A,0))+24*INDEX('6-คาน เหล็กเสริม'!$M:$M,MATCH($B8,'6-คาน เหล็กเสริม'!$A:$A,0))/1000)*INDEX('6-คาน เหล็กเสริม'!$M:$M,MATCH($B8,'6-คาน เหล็กเสริม'!$A:$A,0))^2/162 | R8: =IF(INDEX('6-คาน เหล็กเสริม'!$M:$M,MATCH($B8,'6-คาน เหล็กเสริม'!$A:$A,0))=0,0,2*ROUNDUP(G8/4/INDEX('6-คาน เหล็กเสริม'!$N:$N,MATCH($B8,'6-คาน เหล็กเสริม'!$A:$A,0)),0)+ROUNDUP(G8/2/INDEX('6-คาน เหล็กเสริม'!$O:$O,MATCH($B8,'6-คาน เหล็กเสริม'!$A:$A,0)),0)+1) | S8: =SUM(N8:Q8) | T8: แบบ
A9: B1-006 | B9: B1 | C9: แนว A | D9: 6/A | E9: 7/A | F9: 6 | G9: 5.7 | H9: 0.2 | I9: 0.6 | J9: 0.5 | K9: -0.1 | L9: =H9*I9*G9 | M9: =(2*I9+H9)*G9 | N9: =INDEX('6-คาน เหล็กเสริม'!$E:$E,MATCH($B9,'6-คาน เหล็กเสริม'!$A:$A,0))*(F9+2*INDEX('6-คาน เหล็กเสริม'!$Q:$Q,MATCH($B9,'6-คาน เหล็กเสริม'!$A:$A,0))*INDEX('6-คาน เหล็กเสริม'!$F:$F,MATCH($B9,'6-คาน เหล็กเสริม'!$A:$A,0))/1000)*INDEX('6-คาน เหล็กเสริม'!$F:$F,MATCH($B9,'6-คาน เหล็กเสริม'!$A:$A,0))^2/162 | O9: =INDEX('6-คาน เหล็กเสริม'!$G:$G,MATCH($B9,'6-คาน เหล็กเสริม'!$A:$A,0))*(F9+2*INDEX('6-คาน เหล็กเสริม'!$Q:$Q,MATCH($B9,'6-คาน เหล็กเสริม'!$A:$A,0))*INDEX('6-คาน เหล็กเสริม'!$H:$H,MATCH($B9,'6-คาน เหล็กเสริม'!$A:$A,0))/1000)*INDEX('6-คาน เหล็กเสริม'!$H:$H,MATCH($B9,'6-คาน เหล็กเสริม'!$A:$A,0))^2/162 | P9: =INDEX('6-คาน เหล็กเสริม'!$I:$I,MATCH($B9,'6-คาน เหล็กเสริม'!$A:$A,0))*2*(0.3*G9+INDEX('6-คาน เหล็กเสริม'!$Q:$Q,MATCH($B9,'6-คาน เหล็กเสริม'!$A:$A,0))*INDEX('6-คาน เหล็กเสริม'!$J:$J,MATCH($B9,'6-คาน เหล็กเสริม'!$A:$A,0))/1000)*INDEX('6-คาน เหล็กเสริม'!$J:$J,MATCH($B9,'6-คาน เหล็กเสริม'!$A:$A,0))^2/162+INDEX('6-คาน เหล็กเสริม'!$K:$K,MATCH($B9,'6-คาน เหล็กเสริม'!$A:$A,0))*0.7*G9*INDEX('6-คาน เหล็กเสริม'!$L:$L,MATCH($B9,'6-คาน เหล็กเสริม'!$A:$A,0))^2/162 | Q9: =R9*(2*(H9+I9)-8*INDEX('6-คาน เหล็กเสริม'!$P:$P,MATCH($B9,'6-คาน เหล็กเสริม'!$A:$A,0))+24*INDEX('6-คาน เหล็กเสริม'!$M:$M,MATCH($B9,'6-คาน เหล็กเสริม'!$A:$A,0))/1000)*INDEX('6-คาน เหล็กเสริม'!$M:$M,MATCH($B9,'6-คาน เหล็กเสริม'!$A:$A,0))^2/162 | R9: =IF(INDEX('6-คาน เหล็กเสริม'!$M:$M,MATCH($B9,'6-คาน เหล็กเสริม'!$A:$A,0))=0,0,2*ROUNDUP(G9/4/INDEX('6-คาน เหล็กเสริม'!$N:$N,MATCH($B9,'6-คาน เหล็กเสริม'!$A:$A,0)),0)+ROUNDUP(G9/2/INDEX('6-คาน เหล็กเสริม'!$O:$O,MATCH($B9,'6-คาน เหล็กเสริม'!$A:$A,0)),0)+1) | S9: =SUM(N9:Q9) | T9: แบบ
A10: B1-007 | B10: B1 | C10: แนว A | D10: 7/A | E10: 8/A | F10: 6 | G10: 5.7 | H10: 0.2 | I10: 0.6 | J10: 0.5 | K10: -0.1 | L10: =H10*I10*G10 | M10: =(2*I10+H10)*G10 | N10: =INDEX('6-คาน เหล็กเสริม'!$E:$E,MATCH($B10,'6-คาน เหล็กเสริม'!$A:$A,0))*(F10+2*INDEX('6-คาน เหล็กเสริม'!$Q:$Q,MATCH($B10,'6-คาน เหล็กเสริม'!$A:$A,0))*INDEX('6-คาน เหล็กเสริม'!$F:$F,MATCH($B10,'6-คาน เหล็กเสริม'!$A:$A,0))/1000)*INDEX('6-คาน เหล็กเสริม'!$F:$F,MATCH($B10,'6-คาน เหล็กเสริม'!$A:$A,0))^2/162 | O10: =INDEX('6-คาน เหล็กเสริม'!$G:$G,MATCH($B10,'6-คาน เหล็กเสริม'!$A:$A,0))*(F10+2*INDEX('6-คาน เหล็กเสริม'!$Q:$Q,MATCH($B10,'6-คาน เหล็กเสริม'!$A:$A,0))*INDEX('6-คาน เหล็กเสริม'!$H:$H,MATCH($B10,'6-คาน เหล็กเสริม'!$A:$A,0))/1000)*INDEX('6-คาน เหล็กเสริม'!$H:$H,MATCH($B10,'6-คาน เหล็กเสริม'!$A:$A,0))^2/162 | P10: =INDEX('6-คาน เหล็กเสริม'!$I:$I,MATCH($B10,'6-คาน เหล็กเสริม'!$A:$A,0))*2*(0.3*G10+INDEX('6-คาน เหล็กเสริม'!$Q:$Q,MATCH($B10,'6-คาน เหล็กเสริม'!$A:$A,0))*INDEX('6-คาน เหล็กเสริม'!$J:$J,MATCH($B10,'6-คาน เหล็กเสริม'!$A:$A,0))/1000)*INDEX('6-คาน เหล็กเสริม'!$J:$J,MATCH($B10,'6-คาน เหล็กเสริม'!$A:$A,0))^2/162+INDEX('6-คาน เหล็กเสริม'!$K:$K,MATCH($B10,'6-คาน เหล็กเสริม'!$A:$A,0))*0.7*G10*INDEX('6-คาน เหล็กเสริม'!$L:$L,MATCH($B10,'6-คาน เหล็กเสริม'!$A:$A,0))^2/162 | Q10: =R10*(2*(H10+I10)-8*INDEX('6-คาน เหล็กเสริม'!$P:$P,MATCH($B10,'6-คาน เหล็กเสริม'!$A:$A,0))+24*INDEX('6-คาน เหล็กเสริม'!$M:$M,MATCH($B10,'6-คาน เหล็กเสริม'!$A:$A,0))/1000)*INDEX('6-คาน เหล็กเสริม'!$M:$M,MATCH($B10,'6-คาน เหล็กเสริม'!$A:$A,0))^2/162 | R10: =IF(INDEX('6-คาน เหล็กเสริม'!$M:$M,MATCH($B10,'6-คาน เหล็กเสริม'!$A:$A,0))=0,0,2*ROUNDUP(G10/4/INDEX('6-คาน เหล็กเสริม'!$N:$N,MATCH($B10,'6-คาน เหล็กเสริม'!$A:$A,0)),0)+ROUNDUP(G10/2/INDEX('6-คาน เหล็กเสริม'!$O:$O,MATCH($B10,'6-คาน เหล็กเสริม'!$A:$A,0)),0)+1) | S10: =SUM(N10:Q10) | T10: แบบ
A11: B1-008 | B11: B1 | C11: แนว A | D11: 8/A | E11: 9/A | F11: 6 | G11: 5.7 | H11: 0.2 | I11: 0.6 | J11: 0.5 | K11: -0.1 | L11: =H11*I11*G11 | M11: =(2*I11+H11)*G11 | N11: =INDEX('6-คาน เหล็กเสริม'!$E:$E,MATCH($B11,'6-คาน เหล็กเสริม'!$A:$A,0))*(F11+2*INDEX('6-คาน เหล็กเสริม'!$Q:$Q,MATCH($B11,'6-คาน เหล็กเสริม'!$A:$A,0))*INDEX('6-คาน เหล็กเสริม'!$F:$F,MATCH($B11,'6-คาน เหล็กเสริม'!$A:$A,0))/1000)*INDEX('6-คาน เหล็กเสริม'!$F:$F,MATCH($B11,'6-คาน เหล็กเสริม'!$A:$A,0))^2/162 | O11: =INDEX('6-คาน เหล็กเสริม'!$G:$G,MATCH($B11,'6-คาน เหล็กเสริม'!$A:$A,0))*(F11+2*INDEX('6-คาน เหล็กเสริม'!$Q:$Q,MATCH($B11,'6-คาน เหล็กเสริม'!$A:$A,0))*INDEX('6-คาน เหล็กเสริม'!$H:$H,MATCH($B11,'6-คาน เหล็กเสริม'!$A:$A,0))/1000)*INDEX('6-คาน เหล็กเสริม'!$H:$H,MATCH($B11,'6-คาน เหล็กเสริม'!$A:$A,0))^2/162 | P11: =INDEX('6-คาน เหล็กเสริม'!$I:$I,MATCH($B11,'6-คาน เหล็กเสริม'!$A:$A,0))*2*(0.3*G11+INDEX('6-คาน เหล็กเสริม'!$Q:$Q,MATCH($B11,'6-คาน เหล็กเสริม'!$A:$A,0))*INDEX('6-คาน เหล็กเสริม'!$J:$J,MATCH($B11,'6-คาน เหล็กเสริม'!$A:$A,0))/1000)*INDEX('6-คาน เหล็กเสริม'!$J:$J,MATCH($B11,'6-คาน เหล็กเสริม'!$A:$A,0))^2/162+INDEX('6-คาน เหล็กเสริม'!$K:$K,MATCH($B11,'6-คาน เหล็กเสริม'!$A:$A,0))*0.7*G11*INDEX('6-คาน เหล็กเสริม'!$L:$L,MATCH($B11,'6-คาน เหล็กเสริม'!$A:$A,0))^2/162 | Q11: =R11*(2*(H11+I11)-8*INDEX('6-คาน เหล็กเสริม'!$P:$P,MATCH($B11,'6-คาน เหล็กเสริม'!$A:$A,0))+24*INDEX('6-คาน เหล็กเสริม'!$M:$M,MATCH($B11,'6-คาน เหล็กเสริม'!$A:$A,0))/1000)*INDEX('6-คาน เหล็กเสริม'!$M:$M,MATCH($B11,'6-คาน เหล็กเสริม'!$A:$A,0))^2/162 | R11: =IF(INDEX('6-คาน เหล็กเสริม'!$M:$M,MATCH($B11,'6-คาน เหล็กเสริม'!$A:$A,0))=0,0,2*ROUNDUP(G11/4/INDEX('6-คาน เหล็กเสริม'!$N:$N,MATCH($B11,'6-คาน เหล็กเสริม'!$A:$A,0)),0)+ROUNDUP(G11/2/INDEX('6-คาน เหล็กเสริม'!$O:$O,MATCH($B11,'6-คาน เหล็กเสริม'!$A:$A,0)),0)+1) | S11: =SUM(N11:Q11) | T11: แบบ
A12: B1-009 | B12: B1 | C12: แนว A | D12: 9/A | E12: 10/A | F12: 6 | G12: 5.7 | H12: 0.2 | I12: 0.6 | J12: 0.5 | K12: -0.1 | L12: =H12*I12*G12 | M12: =(2*I12+H12)*G12 | N12: =INDEX('6-คาน เหล็กเสริม'!$E:$E,MATCH($B12,'6-คาน เหล็กเสริม'!$A:$A,0))*(F12+2*INDEX('6-คาน เหล็กเสริม'!$Q:$Q,MATCH($B12,'6-คาน เหล็กเสริม'!$A:$A,0))*INDEX('6-คาน เหล็กเสริม'!$F:$F,MATCH($B12,'6-คาน เหล็กเสริม'!$A:$A,0))/1000)*INDEX('6-คาน เหล็กเสริม'!$F:$F,MATCH($B12,'6-คาน เหล็กเสริม'!$A:$A,0))^2/162 | O12: =INDEX('6-คาน เหล็กเสริม'!$G:$G,MATCH($B12,'6-คาน เหล็กเสริม'!$A:$A,0))*(F12+2*INDEX('6-คาน เหล็กเสริม'!$Q:$Q,MATCH($B12,'6-คาน เหล็กเสริม'!$A:$A,0))*INDEX('6-คาน เหล็กเสริม'!$H:$H,MATCH($B12,'6-คาน เหล็กเสริม'!$A:$A,0))/1000)*INDEX('6-คาน เหล็กเสริม'!$H:$H,MATCH($B12,'6-คาน เหล็กเสริม'!$A:$A,0))^2/162 | P12: =INDEX('6-คาน เหล็กเสริม'!$I:$I,MATCH($B12,'6-คาน เหล็กเสริม'!$A:$A,0))*2*(0.3*G12+INDEX('6-คาน เหล็กเสริม'!$Q:$Q,MATCH($B12,'6-คาน เหล็กเสริม'!$A:$A,0))*INDEX('6-คาน เหล็กเสริม'!$J:$J,MATCH($B12,'6-คาน เหล็กเสริม'!$A:$A,0))/1000)*INDEX('6-คาน เหล็กเสริม'!$J:$J,MATCH($B12,'6-คาน เหล็กเสริม'!$A:$A,0))^2/162+INDEX('6-คาน เหล็กเสริม'!$K:$K,MATCH($B12,'6-คาน เหล็กเสริม'!$A:$A,0))*0.7*G12*INDEX('6-คาน เหล็กเสริม'!$L:$L,MATCH($B12,'6-คาน เหล็กเสริม'!$A:$A,0))^2/162 | Q12: =R12*(2*(H12+I12)-8*INDEX('6-คาน เหล็กเสริม'!$P:$P,MATCH($B12,'6-คาน เหล็กเสริม'!$A:$A,0))+24*INDEX('6-คาน เหล็กเสริม'!$M:$M,MATCH($B12,'6-คาน เหล็กเสริม'!$A:$A,0))/1000)*INDEX('6-คาน เหล็กเสริม'!$M:$M,MATCH($B12,'6-คาน เหล็กเสริม'!$A:$A,0))^2/162 | R12: =IF(INDEX('6-คาน เหล็กเสริม'!$M:$M,MATCH($B12,'6-คาน เหล็กเสริม'!$A:$A,0))=0,0,2*ROUNDUP(G12/4/INDEX('6-คาน เหล็กเสริม'!$N:$N,MATCH($B12,'6-คาน เหล็กเสริม'!$A:$A,0)),0)+ROUNDUP(G12/2/INDEX('6-คาน เหล็กเสริม'!$O:$O,MATCH($B12,'6-คาน เหล็กเสริม'!$A:$A,0)),0)+1) | S12: =SUM(N12:Q12) | T12: แบบ
A13: B1-010 | B13: B1 | C13: แนว A | D13: 10/A | E13: 11/A | F13: 6 | G13: 5.7 | H13: 0.2 | I13: 0.6 | J13: 0.5 | K13: -0.1 | L13: =H13*I13*G13 | M13: =(2*I13+H13)*G13 | N13: =INDEX('6-คาน เหล็กเสริม'!$E:$E,MATCH($B13,'6-คาน เหล็กเสริม'!$A:$A,0))*(F13+2*INDEX('6-คาน เหล็กเสริม'!$Q:$Q,MATCH($B13,'6-คาน เหล็กเสริม'!$A:$A,0))*INDEX('6-คาน เหล็กเสริม'!$F:$F,MATCH($B13,'6-คาน เหล็กเสริม'!$A:$A,0))/1000)*INDEX('6-คาน เหล็กเสริม'!$F:$F,MATCH($B13,'6-คาน เหล็กเสริม'!$A:$A,0))^2/162 | O13: =INDEX('6-คาน เหล็กเสริม'!$G:$G,MATCH($B13,'6-คาน เหล็กเสริม'!$A:$A,0))*(F13+2*INDEX('6-คาน เหล็กเสริม'!$Q:$Q,MATCH($B13,'6-คาน เหล็กเสริม'!$A:$A,0))*INDEX('6-คาน เหล็กเสริม'!$H:$H,MATCH($B13,'6-คาน เหล็กเสริม'!$A:$A,0))/1000)*INDEX('6-คาน เหล็กเสริม'!$H:$H,MATCH($B13,'6-คาน เหล็กเสริม'!$A:$A,0))^2/162 | P13: =INDEX('6-คาน เหล็กเสริม'!$I:$I,MATCH($B13,'6-คาน เหล็กเสริม'!$A:$A,0))*2*(0.3*G13+INDEX('6-คาน เหล็กเสริม'!$Q:$Q,MATCH($B13,'6-คาน เหล็กเสริม'!$A:$A,0))*INDEX('6-คาน เหล็กเสริม'!$J:$J,MATCH($B13,'6-คาน เหล็กเสริม'!$A:$A,0))/1000)*INDEX('6-คาน เหล็กเสริม'!$J:$J,MATCH($B13,'6-คาน เหล็กเสริม'!$A:$A,0))^2/162+INDEX('6-คาน เหล็กเสริม'!$K:$K,MATCH($B13,'6-คาน เหล็กเสริม'!$A:$A,0))*0.7*G13*INDEX('6-คาน เหล็กเสริม'!$L:$L,MATCH($B13,'6-คาน เหล็กเสริม'!$A:$A,0))^2/162 | Q13: =R13*(2*(H13+I13)-8*INDEX('6-คาน เหล็กเสริม'!$P:$P,MATCH($B13,'6-คาน เหล็กเสริม'!$A:$A,0))+24*INDEX('6-คาน เหล็กเสริม'!$M:$M,MATCH($B13,'6-คาน เหล็กเสริม'!$A:$A,0))/1000)*INDEX('6-คาน เหล็กเสริม'!$M:$M,MATCH($B13,'6-คาน เหล็กเสริม'!$A:$A,0))^2/162 | R13: =IF(INDEX('6-คาน เหล็กเสริม'!$M:$M,MATCH($B13,'6-คาน เหล็กเสริม'!$A:$A,0))=0,0,2*ROUNDUP(G13/4/INDEX('6-คาน เหล็กเสริม'!$N:$N,MATCH($B13,'6-คาน เหล็กเสริม'!$A:$A,0)),0)+ROUNDUP(G13/2/INDEX('6-คาน เหล็กเสริม'!$O:$O,MATCH($B13,'6-คาน เหล็กเสริม'!$A:$A,0)),0)+1) | S13: =SUM(N13:Q13) | T13: แบบ
A14: B1-011 | B14: B1 | C14: แนว 1 | D14: 1/A | E14: 1/B | F14: 6 | G14: 5.7 | H14: 0.2 | I14: 0.6 | J14: 0.5 | K14: -0.1 | L14: =H14*I14*G14 | M14: =(2*I14+H14)*G14 | N14: =INDEX('6-คาน เหล็กเสริม'!$E:$E,MATCH($B14,'6-คาน เหล็กเสริม'!$A:$A,0))*(F14+2*INDEX('6-คาน เหล็กเสริม'!$Q:$Q,MATCH($B14,'6-คาน เหล็กเสริม'!$A:$A,0))*INDEX('6-คาน เหล็กเสริม'!$F:$F,MATCH($B14,'6-คาน เหล็กเสริม'!$A:$A,0))/1000)*INDEX('6-คาน เหล็กเสริม'!$F:$F,MATCH($B14,'6-คาน เหล็กเสริม'!$A:$A,0))^2/162 | O14: =INDEX('6-คาน เหล็กเสริม'!$G:$G,MATCH($B14,'6-คาน เหล็กเสริม'!$A:$A,0))*(F14+2*INDEX('6-คาน เหล็กเสริม'!$Q:$Q,MATCH($B14,'6-คาน เหล็กเสริม'!$A:$A,0))*INDEX('6-คาน เหล็กเสริม'!$H:$H,MATCH($B14,'6-คาน เหล็กเสริม'!$A:$A,0))/1000)*INDEX('6-คาน เหล็กเสริม'!$H:$H,MATCH($B14,'6-คาน เหล็กเสริม'!$A:$A,0))^2/162 | P14: =INDEX('6-คาน เหล็กเสริม'!$I:$I,MATCH($B14,'6-คาน เหล็กเสริม'!$A:$A,0))*2*(0.3*G14+INDEX('6-คาน เหล็กเสริม'!$Q:$Q,MATCH($B14,'6-คาน เหล็กเสริม'!$A:$A,0))*INDEX('6-คาน เหล็กเสริม'!$J:$J,MATCH($B14,'6-คาน เหล็กเสริม'!$A:$A,0))/1000)*INDEX('6-คาน เหล็กเสริม'!$J:$J,MATCH($B14,'6-คาน เหล็กเสริม'!$A:$A,0))^2/162+INDEX('6-คาน เหล็กเสริม'!$K:$K,MATCH($B14,'6-คาน เหล็กเสริม'!$A:$A,0))*0.7*G14*INDEX('6-คาน เหล็กเสริม'!$L:$L,MATCH($B14,'6-คาน เหล็กเสริม'!$A:$A,0))^2/162 | Q14: =R14*(2*(H14+I14)-8*INDEX('6-คาน เหล็กเสริม'!$P:$P,MATCH($B14,'6-คาน เหล็กเสริม'!$A:$A,0))+24*INDEX('6-คาน เหล็กเสริม'!$M:$M,MATCH($B14,'6-คาน เหล็กเสริม'!$A:$A,0))/1000)*INDEX('6-คาน เหล็กเสริม'!$M:$M,MATCH($B14,'6-คาน เหล็กเสริม'!$A:$A,0))^2/162 | R14: =IF(INDEX('6-คาน เหล็กเสริม'!$M:$M,MATCH($B14,'6-คาน เหล็กเสริม'!$A:$A,0))=0,0,2*ROUNDUP(G14/4/INDEX('6-คาน เหล็กเสริม'!$N:$N,MATCH($B14,'6-คาน เหล็กเสริม'!$A:$A,0)),0)+ROUNDUP(G14/2/INDEX('6-คาน เหล็กเสริม'!$O:$O,MATCH($B14,'6-คาน เหล็กเสริม'!$A:$A,0)),0)+1) | S14: =SUM(N14:Q14) | T14: แบบ
A15: B1-012 | B15: B1 | C15: แนว 6 | D15: 6/A | E15: 6/B | F15: 6 | G15: 5.7 | H15: 0.2 | I15: 0.6 | J15: 0.5 | K15: -0.1 | L15: =H15*I15*G15 | M15: =(2*I15+H15)*G15 | N15: =INDEX('6-คาน เหล็กเสริม'!$E:$E,MATCH($B15,'6-คาน เหล็กเสริม'!$A:$A,0))*(F15+2*INDEX('6-คาน เหล็กเสริม'!$Q:$Q,MATCH($B15,'6-คาน เหล็กเสริม'!$A:$A,0))*INDEX('6-คาน เหล็กเสริม'!$F:$F,MATCH($B15,'6-คาน เหล็กเสริม'!$A:$A,0))/1000)*INDEX('6-คาน เหล็กเสริม'!$F:$F,MATCH($B15,'6-คาน เหล็กเสริม'!$A:$A,0))^2/162 | O15: =INDEX('6-คาน เหล็กเสริม'!$G:$G,MATCH($B15,'6-คาน เหล็กเสริม'!$A:$A,0))*(F15+2*INDEX('6-คาน เหล็กเสริม'!$Q:$Q,MATCH($B15,'6-คาน เหล็กเสริม'!$A:$A,0))*INDEX('6-คาน เหล็กเสริม'!$H:$H,MATCH($B15,'6-คาน เหล็กเสริม'!$A:$A,0))/1000)*INDEX('6-คาน เหล็กเสริม'!$H:$H,MATCH($B15,'6-คาน เหล็กเสริม'!$A:$A,0))^2/162 | P15: =INDEX('6-คาน เหล็กเสริม'!$I:$I,MATCH($B15,'6-คาน เหล็กเสริม'!$A:$A,0))*2*(0.3*G15+INDEX('6-คาน เหล็กเสริม'!$Q:$Q,MATCH($B15,'6-คาน เหล็กเสริม'!$A:$A,0))*INDEX('6-คาน เหล็กเสริม'!$J:$J,MATCH($B15,'6-คาน เหล็กเสริม'!$A:$A,0))/1000)*INDEX('6-คาน เหล็กเสริม'!$J:$J,MATCH($B15,'6-คาน เหล็กเสริม'!$A:$A,0))^2/162+INDEX('6-คาน เหล็กเสริม'!$K:$K,MATCH($B15,'6-คาน เหล็กเสริม'!$A:$A,0))*0.7*G15*INDEX('6-คาน เหล็กเสริม'!$L:$L,MATCH($B15,'6-คาน เหล็กเสริม'!$A:$A,0))^2/162 | Q15: =R15*(2*(H15+I15)-8*INDEX('6-คาน เหล็กเสริม'!$P:$P,MATCH($B15,'6-คาน เหล็กเสริม'!$A:$A,0))+24*INDEX('6-คาน เหล็กเสริม'!$M:$M,MATCH($B15,'6-คาน เหล็กเสริม'!$A:$A,0))/1000)*INDEX('6-คาน เหล็กเสริม'!$M:$M,MATCH($B15,'6-คาน เหล็กเสริม'!$A:$A,0))^2/162 | R15: =IF(INDEX('6-คาน เหล็กเสริม'!$M:$M,MATCH($B15,'6-คาน เหล็กเสริม'!$A:$A,0))=0,0,2*ROUNDUP(G15/4/INDEX('6-คาน เหล็กเสริม'!$N:$N,MATCH($B15,'6-คาน เหล็กเสริม'!$A:$A,0)),0)+ROUNDUP(G15/2/INDEX('6-คาน เหล็กเสริม'!$O:$O,MATCH($B15,'6-คาน เหล็กเสริม'!$A:$A,0)),0)+1) | S15: =SUM(N15:Q15) | T15: แบบ
... A58: B3-008 | B58: B3 | C58: แนว E+2.01 | D58: 1-4.96/E+2.01 | E58: 1-7.37/E+2.01 | F58: 2.403 | G58: 2.203 | H58: 0.2 | I58: 0.4 | J58: 0.5 | K58: 0.1 | L58: =H58*I58*G58 | M58: =(2*I58+H58)*G58 | N58: =INDEX('6-คาน เหล็กเสริม'!$E:$E,MATCH($B58,'6-คาน เหล็กเสริม'!$A:$A,0))*(F58+2*INDEX('6-คาน เหล็กเสริม'!$Q:$Q,MATCH($B58,'6-คาน เหล็กเสริม'!$A:$A,0))*INDEX('6-คาน เหล็กเสริม'!$F:$F,MATCH($B58,'6-คาน เหล็กเสริม'!$A:$A,0))/1000)*INDEX('6-คาน เหล็กเสริม'!$F:$F,MATCH($B58,'6-คาน เหล็กเสริม'!$A:$A,0))^2/162 | O58: =INDEX('6-คาน เหล็กเสริม'!$G:$G,MATCH($B58,'6-คาน เหล็กเสริม'!$A:$A,0))*(F58+2*INDEX('6-คาน เหล็กเสริม'!$Q:$Q,MATCH($B58,'6-คาน เหล็กเสริม'!$A:$A,0))*INDEX('6-คาน เหล็กเสริม'!$H:$H,MATCH($B58,'6-คาน เหล็กเสริม'!$A:$A,0))/1000)*INDEX('6-คาน เหล็กเสริม'!$H:$H,MATCH($B58,'6-คาน เหล็กเสริม'!$A:$A,0))^2/162 | P58: =INDEX('6-คาน เหล็กเสริม'!$I:$I,MATCH($B58,'6-คาน เหล็กเสริม'!$A:$A,0))*2*(0.3*G58+INDEX('6-คาน เหล็กเสริม'!$Q:$Q,MATCH($B58,'6-คาน เหล็กเสริม'!$A:$A,0))*INDEX('6-คาน เหล็กเสริม'!$J:$J,MATCH($B58,'6-คาน เหล็กเสริม'!$A:$A,0))/1000)*INDEX('6-คาน เหล็กเสริม'!$J:$J,MATCH($B58,'6-คาน เหล็กเสริม'!$A:$A,0))^2/162+INDEX('6-คาน เหล็กเสริม'!$K:$K,MATCH($B58,'6-คาน เหล็กเสริม'!$A:$A,0))*0.7*G58*INDEX('6-คาน เหล็กเสริม'!$L:$L,MATCH($B58,'6-คาน เหล็กเสริม'!$A:$A,0))^2/162 | Q58: =R58*(2*(H58+I58)-8*INDEX('6-คาน เหล็กเสริม'!$P:$P,MATCH($B58,'6-คาน เหล็กเสริม'!$A:$A,0))+24*INDEX('6-คาน เหล็กเสริม'!$M:$M,MATCH($B58,'6-คาน เหล็กเสริม'!$A:$A,0))/1000)*INDEX('6-คาน เหล็กเสริม'!$M:$M,MATCH($B58,'6-คาน เหล็กเสริม'!$A:$A,0))^2/162 | R58: =IF(INDEX('6-คาน เหล็กเสริม'!$M:$M,MATCH($B58,'6-คาน เหล็กเสริม'!$A:$A,0))=0,0,2*ROUNDUP(G58/4/INDEX('6-คาน เหล็กเสริม'!$N:$N,MATCH($B58,'6-คาน เหล็กเสริม'!$A:$A,0)),0)+ROUNDUP(G58/2/INDEX('6-คาน เหล็กเสริม'!$O:$O,MATCH($B58,'6-คาน เหล็กเสริม'!$A:$A,0)),0)+1) | S58: =SUM(N58:Q58) | T58: แบบ S202 (ตำแหน่ง+ระดับ)
A59: LB-001 | B59: LB | C59: แนว A | D59: 1/A | E59: 2/A | F59: 6 | G59: 5.7 | H59: 0.15 | I59: 0.15 | J59: 4.5 | K59: 4.35 | L59: =H59*I59*G59 | M59: =2*I59*G59 | N59: =INDEX('6-คาน เหล็กเสริม'!$E:$E,MATCH($B59,'6-คาน เหล็กเสริม'!$A:$A,0))*(F59+2*INDEX('6-คาน เหล็กเสริม'!$Q:$Q,MATCH($B59,'6-คาน เหล็กเสริม'!$A:$A,0))*INDEX('6-คาน เหล็กเสริม'!$F:$F,MATCH($B59,'6-คาน เหล็กเสริม'!$A:$A,0))/1000)*INDEX('6-คาน เหล็กเสริม'!$F:$F,MATCH($B59,'6-คาน เหล็กเสริม'!$A:$A,0))^2/162 | O59: =INDEX('6-คาน เหล็กเสริม'!$G:$G,MATCH($B59,'6-คาน เหล็กเสริม'!$A:$A,0))*(F59+2*INDEX('6-คาน เหล็กเสริม'!$Q:$Q,MATCH($B59,'6-คาน เหล็กเสริม'!$A:$A,0))*INDEX('6-คาน เหล็กเสริม'!$H:$H,MATCH($B59,'6-คาน เหล็กเสริม'!$A:$A,0))/1000)*INDEX('6-คาน เหล็กเสริม'!$H:$H,MATCH($B59,'6-คาน เหล็กเสริม'!$A:$A,0))^2/162 | P59: =INDEX('6-คาน เหล็กเสริม'!$I:$I,MATCH($B59,'6-คาน เหล็กเสริม'!$A:$A,0))*2*(0.3*G59+INDEX('6-คาน เหล็กเสริม'!$Q:$Q,MATCH($B59,'6-คาน เหล็กเสริม'!$A:$A,0))*INDEX('6-คาน เหล็กเสริม'!$J:$J,MATCH($B59,'6-คาน เหล็กเสริม'!$A:$A,0))/1000)*INDEX('6-คาน เหล็กเสริม'!$J:$J,MATCH($B59,'6-คาน เหล็กเสริม'!$A:$A,0))^2/162+INDEX('6-คาน เหล็กเสริม'!$K:$K,MATCH($B59,'6-คาน เหล็กเสริม'!$A:$A,0))*0.7*G59*INDEX('6-คาน เหล็กเสริม'!$L:$L,MATCH($B59,'6-คาน เหล็กเสริม'!$A:$A,0))^2/162 | Q59: =R59*(2*(H59+I59)-8*INDEX('6-คาน เหล็กเสริม'!$P:$P,MATCH($B59,'6-คาน เหล็กเสริม'!$A:$A,0))+24*INDEX('6-คาน เหล็กเสริม'!$M:$M,MATCH($B59,'6-คาน เหล็กเสริม'!$A:$A,0))/1000)*INDEX('6-คาน เหล็กเสริม'!$M:$M,MATCH($B59,'6-คาน เหล็กเสริม'!$A:$A,0))^2/162 | R59: =IF(INDEX('6-คาน เหล็กเสริม'!$M:$M,MATCH($B59,'6-คาน เหล็กเสริม'!$A:$A,0))=0,0,2*ROUNDUP(G59/4/INDEX('6-คาน เหล็กเสริม'!$N:$N,MATCH($B59,'6-คาน เหล็กเสริม'!$A:$A,0)),0)+ROUNDUP(G59/2/INDEX('6-คาน เหล็กเสริม'!$O:$O,MATCH($B59,'6-คาน เหล็กเสริม'!$A:$A,0)),0)+1) | S59: =SUM(N59:Q59) | T59: ผู้ว่าจ้างกำหนดระดับ
A60: LB-002 | B60: LB | C60: แนว A | D60: 2/A | E60: 3/A | F60: 6 | G60: 5.7 | H60: 0.15 | I60: 0.15 | J60: 4.5 | K60: 4.35 | L60: =H60*I60*G60 | M60: =2*I60*G60 | N60: =INDEX('6-คาน เหล็กเสริม'!$E:$E,MATCH($B60,'6-คาน เหล็กเสริม'!$A:$A,0))*(F60+2*INDEX('6-คาน เหล็กเสริม'!$Q:$Q,MATCH($B60,'6-คาน เหล็กเสริม'!$A:$A,0))*INDEX('6-คาน เหล็กเสริม'!$F:$F,MATCH($B60,'6-คาน เหล็กเสริม'!$A:$A,0))/1000)*INDEX('6-คาน เหล็กเสริม'!$F:$F,MATCH($B60,'6-คาน เหล็กเสริม'!$A:$A,0))^2/162 | O60: =INDEX('6-คาน เหล็กเสริม'!$G:$G,MATCH($B60,'6-คาน เหล็กเสริม'!$A:$A,0))*(F60+2*INDEX('6-คาน เหล็กเสริม'!$Q:$Q,MATCH($B60,'6-คาน เหล็กเสริม'!$A:$A,0))*INDEX('6-คาน เหล็กเสริม'!$H:$H,MATCH($B60,'6-คาน เหล็กเสริม'!$A:$A,0))/1000)*INDEX('6-คาน เหล็กเสริม'!$H:$H,MATCH($B60,'6-คาน เหล็กเสริม'!$A:$A,0))^2/162 | P60: =INDEX('6-คาน เหล็กเสริม'!$I:$I,MATCH($B60,'6-คาน เหล็กเสริม'!$A:$A,0))*2*(0.3*G60+INDEX('6-คาน เหล็กเสริม'!$Q:$Q,MATCH($B60,'6-คาน เหล็กเสริม'!$A:$A,0))*INDEX('6-คาน เหล็กเสริม'!$J:$J,MATCH($B60,'6-คาน เหล็กเสริม'!$A:$A,0))/1000)*INDEX('6-คาน เหล็กเสริม'!$J:$J,MATCH($B60,'6-คาน เหล็กเสริม'!$A:$A,0))^2/162+INDEX('6-คาน เหล็กเสริม'!$K:$K,MATCH($B60,'6-คาน เหล็กเสริม'!$A:$A,0))*0.7*G60*INDEX('6-คาน เหล็กเสริม'!$L:$L,MATCH($B60,'6-คาน เหล็กเสริม'!$A:$A,0))^2/162 | Q60: =R60*(2*(H60+I60)-8*INDEX('6-คาน เหล็กเสริม'!$P:$P,MATCH($B60,'6-คาน เหล็กเสริม'!$A:$A,0))+24*INDEX('6-คาน เหล็กเสริม'!$M:$M,MATCH($B60,'6-คาน เหล็กเสริม'!$A:$A,0))/1000)*INDEX('6-คาน เหล็กเสริม'!$M:$M,MATCH($B60,'6-คาน เหล็กเสริม'!$A:$A,0))^2/162 | R60: =IF(INDEX('6-คาน เหล็กเสริม'!$M:$M,MATCH($B60,'6-คาน เหล็กเสริม'!$A:$A,0))=0,0,2*ROUNDUP(G60/4/INDEX('6-คาน เหล็กเสริม'!$N:$N,MATCH($B60,'6-คาน เหล็กเสริม'!$A:$A,0)),0)+ROUNDUP(G60/2/INDEX('6-คาน เหล็กเสริม'!$O:$O,MATCH($B60,'6-คาน เหล็กเสริม'!$A:$A,0)),0)+1) | S60: =SUM(N60:Q60) | T60: ผู้ว่าจ้างกำหนดระดับ
A61: LB-003 | B61: LB | C61: แนว A | D61: 3/A | E61: 4/A | F61: 6 | G61: 5.7 | H61: 0.15 | I61: 0.15 | J61: 4.5 | K61: 4.35 | L61: =H61*I61*G61 | M61: =2*I61*G61 | N61: =INDEX('6-คาน เหล็กเสริม'!$E:$E,MATCH($B61,'6-คาน เหล็กเสริม'!$A:$A,0))*(F61+2*INDEX('6-คาน เหล็กเสริม'!$Q:$Q,MATCH($B61,'6-คาน เหล็กเสริม'!$A:$A,0))*INDEX('6-คาน เหล็กเสริม'!$F:$F,MATCH($B61,'6-คาน เหล็กเสริม'!$A:$A,0))/1000)*INDEX('6-คาน เหล็กเสริม'!$F:$F,MATCH($B61,'6-คาน เหล็กเสริม'!$A:$A,0))^2/162 | O61: =INDEX('6-คาน เหล็กเสริม'!$G:$G,MATCH($B61,'6-คาน เหล็กเสริม'!$A:$A,0))*(F61+2*INDEX('6-คาน เหล็กเสริม'!$Q:$Q,MATCH($B61,'6-คาน เหล็กเสริม'!$A:$A,0))*INDEX('6-คาน เหล็กเสริม'!$H:$H,MATCH($B61,'6-คาน เหล็กเสริม'!$A:$A,0))/1000)*INDEX('6-คาน เหล็กเสริม'!$H:$H,MATCH($B61,'6-คาน เหล็กเสริม'!$A:$A,0))^2/162 | P61: =INDEX('6-คาน เหล็กเสริม'!$I:$I,MATCH($B61,'6-คาน เหล็กเสริม'!$A:$A,0))*2*(0.3*G61+INDEX('6-คาน เหล็กเสริม'!$Q:$Q,MATCH($B61,'6-คาน เหล็กเสริม'!$A:$A,0))*INDEX('6-คาน เหล็กเสริม'!$J:$J,MATCH($B61,'6-คาน เหล็กเสริม'!$A:$A,0))/1000)*INDEX('6-คาน เหล็กเสริม'!$J:$J,MATCH($B61,'6-คาน เหล็กเสริม'!$A:$A,0))^2/162+INDEX('6-คาน เหล็กเสริม'!$K:$K,MATCH($B61,'6-คาน เหล็กเสริม'!$A:$A,0))*0.7*G61*INDEX('6-คาน เหล็กเสริม'!$L:$L,MATCH($B61,'6-คาน เหล็กเสริม'!$A:$A,0))^2/162 | Q61: =R61*(2*(H61+I61)-8*INDEX('6-คาน เหล็กเสริม'!$P:$P,MATCH($B61,'6-คาน เหล็กเสริม'!$A:$A,0))+24*INDEX('6-คาน เหล็กเสริม'!$M:$M,MATCH($B61,'6-คาน เหล็กเสริม'!$A:$A,0))/1000)*INDEX('6-คาน เหล็กเสริม'!$M:$M,MATCH($B61,'6-คาน เหล็กเสริม'!$A:$A,0))^2/162 | R61: =IF(INDEX('6-คาน เหล็กเสริม'!$M:$M,MATCH($B61,'6-คาน เหล็กเสริม'!$A:$A,0))=0,0,2*ROUNDUP(G61/4/INDEX('6-คาน เหล็กเสริม'!$N:$N,MATCH($B61,'6-คาน เหล็กเสริม'!$A:$A,0)),0)+ROUNDUP(G61/2/INDEX('6-คาน เหล็กเสริม'!$O:$O,MATCH($B61,'6-คาน เหล็กเสริม'!$A:$A,0)),0)+1) | S61: =SUM(N61:Q61) | T61: ผู้ว่าจ้างกำหนดระดับ
A62: LB-004 | B62: LB | C62: แนว A | D62: 4/A | E62: 5/A | F62: 6 | G62: 5.7 | H62: 0.15 | I62: 0.15 | J62: 4.5 | K62: 4.35 | L62: =H62*I62*G62 | M62: =2*I62*G62 | N62: =INDEX('6-คาน เหล็กเสริม'!$E:$E,MATCH($B62,'6-คาน เหล็กเสริม'!$A:$A,0))*(F62+2*INDEX('6-คาน เหล็กเสริม'!$Q:$Q,MATCH($B62,'6-คาน เหล็กเสริม'!$A:$A,0))*INDEX('6-คาน เหล็กเสริม'!$F:$F,MATCH($B62,'6-คาน เหล็กเสริม'!$A:$A,0))/1000)*INDEX('6-คาน เหล็กเสริม'!$F:$F,MATCH($B62,'6-คาน เหล็กเสริม'!$A:$A,0))^2/162 | O62: =INDEX('6-คาน เหล็กเสริม'!$G:$G,MATCH($B62,'6-คาน เหล็กเสริม'!$A:$A,0))*(F62+2*INDEX('6-คาน เหล็กเสริม'!$Q:$Q,MATCH($B62,'6-คาน เหล็กเสริม'!$A:$A,0))*INDEX('6-คาน เหล็กเสริม'!$H:$H,MATCH($B62,'6-คาน เหล็กเสริม'!$A:$A,0))/1000)*INDEX('6-คาน เหล็กเสริม'!$H:$H,MATCH($B62,'6-คาน เหล็กเสริม'!$A:$A,0))^2/162 | P62: =INDEX('6-คาน เหล็กเสริม'!$I:$I,MATCH($B62,'6-คาน เหล็กเสริม'!$A:$A,0))*2*(0.3*G62+INDEX('6-คาน เหล็กเสริม'!$Q:$Q,MATCH($B62,'6-คาน เหล็กเสริม'!$A:$A,0))*INDEX('6-คาน เหล็กเสริม'!$J:$J,MATCH($B62,'6-คาน เหล็กเสริม'!$A:$A,0))/1000)*INDEX('6-คาน เหล็กเสริม'!$J:$J,MATCH($B62,'6-คาน เหล็กเสริม'!$A:$A,0))^2/162+INDEX('6-คาน เหล็กเสริม'!$K:$K,MATCH($B62,'6-คาน เหล็กเสริม'!$A:$A,0))*0.7*G62*INDEX('6-คาน เหล็กเสริม'!$L:$L,MATCH($B62,'6-คาน เหล็กเสริม'!$A:$A,0))^2/162 | Q62: =R62*(2*(H62+I62)-8*INDEX('6-คาน เหล็กเสริม'!$P:$P,MATCH($B62,'6-คาน เหล็กเสริม'!$A:$A,0))+24*INDEX('6-คาน เหล็กเสริม'!$M:$M,MATCH($B62,'6-คาน เหล็กเสริม'!$A:$A,0))/1000)*INDEX('6-คาน เหล็กเสริม'!$M:$M,MATCH($B62,'6-คาน เหล็กเสริม'!$A:$A,0))^2/162 | R62: =IF(INDEX('6-คาน เหล็กเสริม'!$M:$M,MATCH($B62,'6-คาน เหล็กเสริม'!$A:$A,0))=0,0,2*ROUNDUP(G62/4/INDEX('6-คาน เหล็กเสริม'!$N:$N,MATCH($B62,'6-คาน เหล็กเสริม'!$A:$A,0)),0)+ROUNDUP(G62/2/INDEX('6-คาน เหล็กเสริม'!$O:$O,MATCH($B62,'6-คาน เหล็กเสริม'!$A:$A,0)),0)+1) | S62: =SUM(N62:Q62) | T62: ผู้ว่าจ้างกำหนดระดับ
A63: LB-005 | B63: LB | C63: แนว A | D63: 6/A | E63: 7/A | F63: 6 | G63: 5.7 | H63: 0.15 | I63: 0.15 | J63: 4.5 | K63: 4.35 | L63: =H63*I63*G63 | M63: =2*I63*G63 | N63: =INDEX('6-คาน เหล็กเสริม'!$E:$E,MATCH($B63,'6-คาน เหล็กเสริม'!$A:$A,0))*(F63+2*INDEX('6-คาน เหล็กเสริม'!$Q:$Q,MATCH($B63,'6-คาน เหล็กเสริม'!$A:$A,0))*INDEX('6-คาน เหล็กเสริม'!$F:$F,MATCH($B63,'6-คาน เหล็กเสริม'!$A:$A,0))/1000)*INDEX('6-คาน เหล็กเสริม'!$F:$F,MATCH($B63,'6-คาน เหล็กเสริม'!$A:$A,0))^2/162 | O63: =INDEX('6-คาน เหล็กเสริม'!$G:$G,MATCH($B63,'6-คาน เหล็กเสริม'!$A:$A,0))*(F63+2*INDEX('6-คาน เหล็กเสริม'!$Q:$Q,MATCH($B63,'6-คาน เหล็กเสริม'!$A:$A,0))*INDEX('6-คาน เหล็กเสริม'!$H:$H,MATCH($B63,'6-คาน เหล็กเสริม'!$A:$A,0))/1000)*INDEX('6-คาน เหล็กเสริม'!$H:$H,MATCH($B63,'6-คาน เหล็กเสริม'!$A:$A,0))^2/162 | P63: =INDEX('6-คาน เหล็กเสริม'!$I:$I,MATCH($B63,'6-คาน เหล็กเสริม'!$A:$A,0))*2*(0.3*G63+INDEX('6-คาน เหล็กเสริม'!$Q:$Q,MATCH($B63,'6-คาน เหล็กเสริม'!$A:$A,0))*INDEX('6-คาน เหล็กเสริม'!$J:$J,MATCH($B63,'6-คาน เหล็กเสริม'!$A:$A,0))/1000)*INDEX('6-คาน เหล็กเสริม'!$J:$J,MATCH($B63,'6-คาน เหล็กเสริม'!$A:$A,0))^2/162+INDEX('6-คาน เหล็กเสริม'!$K:$K,MATCH($B63,'6-คาน เหล็กเสริม'!$A:$A,0))*0.7*G63*INDEX('6-คาน เหล็กเสริม'!$L:$L,MATCH($B63,'6-คาน เหล็กเสริม'!$A:$A,0))^2/162 | Q63: =R63*(2*(H63+I63)-8*INDEX('6-คาน เหล็กเสริม'!$P:$P,MATCH($B63,'6-คาน เหล็กเสริม'!$A:$A,0))+24*INDEX('6-คาน เหล็กเสริม'!$M:$M,MATCH($B63,'6-คาน เหล็กเสริม'!$A:$A,0))/1000)*INDEX('6-คาน เหล็กเสริม'!$M:$M,MATCH($B63,'6-คาน เหล็กเสริม'!$A:$A,0))^2/162 | R63: =IF(INDEX('6-คาน เหล็กเสริม'!$M:$M,MATCH($B63,'6-คาน เหล็กเสริม'!$A:$A,0))=0,0,2*ROUNDUP(G63/4/INDEX('6-คาน เหล็กเสริม'!$N:$N,MATCH($B63,'6-คาน เหล็กเสริม'!$A:$A,0)),0)+ROUNDUP(G63/2/INDEX('6-คาน เหล็กเสริม'!$O:$O,MATCH($B63,'6-คาน เหล็กเสริม'!$A:$A,0)),0)+1) | S63: =SUM(N63:Q63) | T63: ผู้ว่าจ้างกำหนดระดับ
A64: LB-006 | B64: LB | C64: แนว A | D64: 7/A | E64: 8/A | F64: 6 | G64: 5.7 | H64: 0.15 | I64: 0.15 | J64: 4.5 | K64: 4.35 | L64: =H64*I64*G64 | M64: =2*I64*G64 | N64: =INDEX('6-คาน เหล็กเสริม'!$E:$E,MATCH($B64,'6-คาน เหล็กเสริม'!$A:$A,0))*(F64+2*INDEX('6-คาน เหล็กเสริม'!$Q:$Q,MATCH($B64,'6-คาน เหล็กเสริม'!$A:$A,0))*INDEX('6-คาน เหล็กเสริม'!$F:$F,MATCH($B64,'6-คาน เหล็กเสริม'!$A:$A,0))/1000)*INDEX('6-คาน เหล็กเสริม'!$F:$F,MATCH($B64,'6-คาน เหล็กเสริม'!$A:$A,0))^2/162 | O64: =INDEX('6-คาน เหล็กเสริม'!$G:$G,MATCH($B64,'6-คาน เหล็กเสริม'!$A:$A,0))*(F64+2*INDEX('6-คาน เหล็กเสริม'!$Q:$Q,MATCH($B64,'6-คาน เหล็กเสริม'!$A:$A,0))*INDEX('6-คาน เหล็กเสริม'!$H:$H,MATCH($B64,'6-คาน เหล็กเสริม'!$A:$A,0))/1000)*INDEX('6-คาน เหล็กเสริม'!$H:$H,MATCH($B64,'6-คาน เหล็กเสริม'!$A:$A,0))^2/162 | P64: =INDEX('6-คาน เหล็กเสริม'!$I:$I,MATCH($B64,'6-คาน เหล็กเสริม'!$A:$A,0))*2*(0.3*G64+INDEX('6-คาน เหล็กเสริม'!$Q:$Q,MATCH($B64,'6-คาน เหล็กเสริม'!$A:$A,0))*INDEX('6-คาน เหล็กเสริม'!$J:$J,MATCH($B64,'6-คาน เหล็กเสริม'!$A:$A,0))/1000)*INDEX('6-คาน เหล็กเสริม'!$J:$J,MATCH($B64,'6-คาน เหล็กเสริม'!$A:$A,0))^2/162+INDEX('6-คาน เหล็กเสริม'!$K:$K,MATCH($B64,'6-คาน เหล็กเสริม'!$A:$A,0))*0.7*G64*INDEX('6-คาน เหล็กเสริม'!$L:$L,MATCH($B64,'6-คาน เหล็กเสริม'!$A:$A,0))^2/162 | Q64: =R64*(2*(H64+I64)-8*INDEX('6-คาน เหล็กเสริม'!$P:$P,MATCH($B64,'6-คาน เหล็กเสริม'!$A:$A,0))+24*INDEX('6-คาน เหล็กเสริม'!$M:$M,MATCH($B64,'6-คาน เหล็กเสริม'!$A:$A,0))/1000)*INDEX('6-คาน เหล็กเสริม'!$M:$M,MATCH($B64,'6-คาน เหล็กเสริม'!$A:$A,0))^2/162 | R64: =IF(INDEX('6-คาน เหล็กเสริม'!$M:$M,MATCH($B64,'6-คาน เหล็กเสริม'!$A:$A,0))=0,0,2*ROUNDUP(G64/4/INDEX('6-คาน เหล็กเสริม'!$N:$N,MATCH($B64,'6-คาน เหล็กเสริม'!$A:$A,0)),0)+ROUNDUP(G64/2/INDEX('6-คาน เหล็กเสริม'!$O:$O,MATCH($B64,'6-คาน เหล็กเสริม'!$A:$A,0)),0)+1) | S64: =SUM(N64:Q64) | T64: ผู้ว่าจ้างกำหนดระดับ
